{
 "cells": [
  {
   "cell_type": "code",
   "execution_count": 2,
   "id": "9030f075-40f9-426d-82e0-d6a1fbda43d8",
   "metadata": {},
   "outputs": [
    {
     "ename": "NameError",
     "evalue": "name 'core' is not defined",
     "output_type": "error",
     "traceback": [
      "\u001b[1;31m---------------------------------------------------------------------------\u001b[0m",
      "\u001b[1;31mNameError\u001b[0m                                 Traceback (most recent call last)",
      "Cell \u001b[1;32mIn[2], line 2\u001b[0m\n\u001b[0;32m      1\u001b[0m \u001b[38;5;28;01mimport\u001b[39;00m \u001b[38;5;21;01mcv2\u001b[39;00m\n\u001b[1;32m----> 2\u001b[0m \u001b[38;5;28;01mimport\u001b[39;00m \u001b[38;5;21;01mmediapipe\u001b[39;00m \u001b[38;5;28;01mas\u001b[39;00m \u001b[38;5;21;01mmp\u001b[39;00m\n\u001b[0;32m      3\u001b[0m \u001b[38;5;28;01mimport\u001b[39;00m \u001b[38;5;21;01mnumpy\u001b[39;00m \u001b[38;5;28;01mas\u001b[39;00m \u001b[38;5;21;01mnp\u001b[39;00m\n\u001b[0;32m      4\u001b[0m \u001b[38;5;28;01mimport\u001b[39;00m \u001b[38;5;21;01mtensorflow\u001b[39;00m \u001b[38;5;28;01mas\u001b[39;00m \u001b[38;5;21;01mtf\u001b[39;00m\n",
      "File \u001b[1;32m~\\AppData\\Roaming\\Python\\Python39\\site-packages\\mediapipe\\__init__.py:17\u001b[0m\n\u001b[0;32m     15\u001b[0m \u001b[38;5;28;01mfrom\u001b[39;00m \u001b[38;5;21;01mmediapipe\u001b[39;00m\u001b[38;5;21;01m.\u001b[39;00m\u001b[38;5;21;01mpython\u001b[39;00m \u001b[38;5;28;01mimport\u001b[39;00m \u001b[38;5;241m*\u001b[39m\n\u001b[0;32m     16\u001b[0m \u001b[38;5;28;01mimport\u001b[39;00m \u001b[38;5;21;01mmediapipe\u001b[39;00m\u001b[38;5;21;01m.\u001b[39;00m\u001b[38;5;21;01mpython\u001b[39;00m\u001b[38;5;21;01m.\u001b[39;00m\u001b[38;5;21;01msolutions\u001b[39;00m \u001b[38;5;28;01mas\u001b[39;00m \u001b[38;5;21;01msolutions\u001b[39;00m \n\u001b[1;32m---> 17\u001b[0m \u001b[38;5;28;01mimport\u001b[39;00m \u001b[38;5;21;01mmediapipe\u001b[39;00m\u001b[38;5;21;01m.\u001b[39;00m\u001b[38;5;21;01mtasks\u001b[39;00m\u001b[38;5;21;01m.\u001b[39;00m\u001b[38;5;21;01mpython\u001b[39;00m \u001b[38;5;28;01mas\u001b[39;00m \u001b[38;5;21;01mtasks\u001b[39;00m\n\u001b[0;32m     20\u001b[0m \u001b[38;5;28;01mdel\u001b[39;00m framework\n\u001b[0;32m     21\u001b[0m \u001b[38;5;28;01mdel\u001b[39;00m gpu\n",
      "File \u001b[1;32m~\\AppData\\Roaming\\Python\\Python39\\site-packages\\mediapipe\\tasks\\python\\__init__.py:17\u001b[0m\n\u001b[0;32m      1\u001b[0m \u001b[38;5;66;03m# Copyright 2022 The MediaPipe Authors.\u001b[39;00m\n\u001b[0;32m      2\u001b[0m \u001b[38;5;66;03m#\u001b[39;00m\n\u001b[0;32m      3\u001b[0m \u001b[38;5;66;03m# Licensed under the Apache License, Version 2.0 (the \"License\");\u001b[39;00m\n\u001b[1;32m   (...)\u001b[0m\n\u001b[0;32m     12\u001b[0m \u001b[38;5;66;03m# See the License for the specific language governing permissions and\u001b[39;00m\n\u001b[0;32m     13\u001b[0m \u001b[38;5;66;03m# limitations under the License.\u001b[39;00m\n\u001b[0;32m     15\u001b[0m \u001b[38;5;124;03m\"\"\"MediaPipe Tasks API.\"\"\"\u001b[39;00m\n\u001b[1;32m---> 17\u001b[0m \u001b[38;5;28;01mfrom\u001b[39;00m \u001b[38;5;21;01m.\u001b[39;00m \u001b[38;5;28;01mimport\u001b[39;00m audio\n\u001b[0;32m     18\u001b[0m \u001b[38;5;28;01mfrom\u001b[39;00m \u001b[38;5;21;01m.\u001b[39;00m \u001b[38;5;28;01mimport\u001b[39;00m components\n\u001b[0;32m     19\u001b[0m \u001b[38;5;28;01mfrom\u001b[39;00m \u001b[38;5;21;01m.\u001b[39;00m \u001b[38;5;28;01mimport\u001b[39;00m core\n",
      "File \u001b[1;32m~\\AppData\\Roaming\\Python\\Python39\\site-packages\\mediapipe\\tasks\\python\\audio\\__init__.py:27\u001b[0m\n\u001b[0;32m     25\u001b[0m AudioEmbedderOptions \u001b[38;5;241m=\u001b[39m audio_embedder\u001b[38;5;241m.\u001b[39mAudioEmbedderOptions\n\u001b[0;32m     26\u001b[0m AudioEmbedderResult \u001b[38;5;241m=\u001b[39m audio_embedder\u001b[38;5;241m.\u001b[39mAudioEmbedderResult\n\u001b[1;32m---> 27\u001b[0m RunningMode \u001b[38;5;241m=\u001b[39m \u001b[43mcore\u001b[49m\u001b[38;5;241m.\u001b[39maudio_task_running_mode\u001b[38;5;241m.\u001b[39mAudioTaskRunningMode\n\u001b[0;32m     29\u001b[0m \u001b[38;5;66;03m# Remove unnecessary modules to avoid duplication in API docs.\u001b[39;00m\n\u001b[0;32m     30\u001b[0m \u001b[38;5;28;01mdel\u001b[39;00m audio_classifier\n",
      "\u001b[1;31mNameError\u001b[0m: name 'core' is not defined"
     ]
    }
   ],
   "source": [
    "import cv2\n",
    "import mediapipe as mp\n",
    "import numpy as np\n",
    "import tensorflow as tf\n"
   ]
  },
  {
   "cell_type": "code",
   "execution_count": null,
   "id": "09e29f95-db8e-448f-8a63-f9d19f1419eb",
   "metadata": {
    "scrolled": true
   },
   "outputs": [],
   "source": [
    "# Define drawing and landmark utility functions\n",
    "mp_drawing = mp.solutions.drawing_utils\n",
    "mp_hands = mp.solutions.hands\n",
    "\n",
    "# Initialize hand landmark detection with specific parameters\n",
    "hands = mp_hands.Hands(min_detection_confidence=0.5, min_tracking_confidence=0.5, max_num_hands=2)\n",
    "\n",
    "# Video capture setup\n",
    "cap = cv2.VideoCapture(0)\n",
    "\n",
    "while cap.isOpened():\n",
    "    success, image = cap.read()\n",
    "    if not success:\n",
    "        print(\"Ignoring empty camera frame.\")\n",
    "        continue\n",
    "\n",
    "    # RGB to BGR conversion for MediaPipe\n",
    "    image = cv2.cvtColor(image, cv2.COLOR_BGR2RGB)\n",
    "    image = cv2.resize(image, (75, 75))\n",
    "    # Hand landmark detection\n",
    "    results = hands.process(image)\n",
    "\n",
    "    # Draw hand landmarks and bounding box on the image\n",
    "    if results.multi_hand_landmarks:\n",
    "        for hand_landmarks in results.multi_hand_landmarks:\n",
    "            for idx, landmark in enumerate(hand_landmarks.landmark):\n",
    "                x = int(landmark.x * image.shape[1])\n",
    "                y = int(landmark.y * image.shape[0])\n",
    "                cv2.putText(image, str(idx), (x, y), cv2.FONT_HERSHEY_SIMPLEX, 0.5, (0, 255, 0), 2)\n",
    "\n",
    "    # Display the processed image with landmarks\n",
    "    cv2.imshow('Test', cv2.flip(image, 1))\n",
    "    if cv2.waitKey(5) & 0xFF == ord('q'):\n",
    "        break\n",
    "\n",
    "# When all the process is done\n",
    "# Release the capture and destroy all windows\n",
    "cap.release()\n",
    "cv2.destroyAllWindows()"
   ]
  },
  {
   "cell_type": "code",
   "execution_count": 2,
   "id": "f53706a9-d9f0-4dcb-acd6-8cbbe9327da9",
   "metadata": {},
   "outputs": [],
   "source": [
    "import cv2\n",
    "\n",
    "image = cv2.imread('../datasets/Filtered Raw Images/Aku/annotated_000008.jpg')\n",
    "image = cv2.cvtColor(image, cv2.COLOR_BGR2RGB)\n",
    "image = cv2.resize(image, (240, 240))\n",
    "cv2.imshow('awda', image)\n",
    "cv2.waitKey(0)  # Add this line to wait indefinitely for a key press\n",
    "cv2.destroyAllWindows()  # Add this line to close all OpenCV windows after a key press\n"
   ]
  },
  {
   "cell_type": "code",
   "execution_count": 24,
   "id": "ac670dc1-b9b7-4285-bb3e-7936ba4dcc37",
   "metadata": {},
   "outputs": [
    {
     "data": {
      "text/plain": [
       "array([[ 1,  3, 43,  6,  5]])"
      ]
     },
     "execution_count": 24,
     "metadata": {},
     "output_type": "execute_result"
    }
   ],
   "source": [
    "np.array([1,3,43,6,5]).reshape(1, -1)"
   ]
  },
  {
   "cell_type": "code",
   "execution_count": 30,
   "id": "c016eca6-7512-485a-83ec-3fa5f88a5f22",
   "metadata": {},
   "outputs": [
    {
     "name": "stdout",
     "output_type": "stream",
     "text": [
      "[['A_0.jpg' -1.7815987986568862 0.5958334327417503 0.6353401246010253\n",
      "  -1.6699358919913159 0.8230597988173596 -0.6783253341414758\n",
      "  -1.3515750268349014 0.912997413369571 -0.9133481667728659\n",
      "  -1.017809495811953 0.9646039992320188 -1.0925566078553028\n",
      "  -0.674402759052964 0.9725940193365538 -1.2352716576600598\n",
      "  -1.124710654667919 0.5834635521676054 -1.1535814548455496\n",
      "  -0.6677210796979521 0.5594375833815637 -1.486347398524908\n",
      "  -0.3102582627069685 0.528237838195568 -1.588895196517843\n",
      "  -0.03732832173647564 0.4590032171029787 -1.6537175216829747\n",
      "  -1.306796819329158 0.40429750269682785 -1.534713118425242\n",
      "  -0.9261463360266025 0.6168771381218267 -1.934236681747126\n",
      "  -1.1276139844683888 0.8610218267641183 -1.89248719792594\n",
      "  -1.346145352623372 0.8987320038908418 -1.745859985669686\n",
      "  -1.5201434098932014 0.2955069259077762 -1.8248551038201593\n",
      "  -1.3170727710725814 0.6021925556938819 -2.1094006551408566\n",
      "  -1.5145870373182155 0.7790785888717825 -1.8978080619239552\n",
      "  -1.6577049298714954 0.7451795973864973 -1.5850596481222547\n",
      "  -1.7449549991477658 0.23627774088119394 -1.9419569027960604\n",
      "  -1.5743383520462475 0.47800302612642087 -2.0779526090210116\n",
      "  -1.6512401913246693 0.6607914564566146 -1.87090744469093\n",
      "  -1.7425866461501374 0.6711005002687177 -1.6243566295073768 'A']]\n"
     ]
    },
    {
     "name": "stderr",
     "output_type": "stream",
     "text": [
      "C:\\Users\\ASUS TUF\\AppData\\Roaming\\Python\\Python39\\site-packages\\sklearn\\base.py:376: InconsistentVersionWarning: Trying to unpickle estimator StandardScaler from version 1.5.0 when using version 1.4.2. This might lead to breaking code or invalid results. Use at your own risk. For more info please refer to:\n",
      "https://scikit-learn.org/stable/model_persistence.html#security-maintainability-limitations\n",
      "  warnings.warn(\n",
      "C:\\Users\\ASUS TUF\\AppData\\Roaming\\Python\\Python39\\site-packages\\sklearn\\base.py:493: UserWarning: X does not have valid feature names, but StandardScaler was fitted with feature names\n",
      "  warnings.warn(\n"
     ]
    }
   ],
   "source": [
    "import joblib\n",
    "import numpy as np\n",
    "import pandas as pd\n",
    "\n",
    "sample = pd.read_csv('../fix-data.csv')\n",
    "sample = np.array(sample)\n",
    "scaler = joblib.load(\"scaler.pkl\")\n",
    "\n",
    "for i in range(len(samples[:5])):\n",
    "    current_sample = sample[i][1:-1] \n",
    "    current_sample = np.array(current_sample).reshape(1, -1)\n",
    "    transformed_sample = scaler.transform(current_sample)\n",
    "    sample[i][1:-1] = transformed_sample.flatten() \n",
    "    break\n",
    "    # without scaler\n",
    "    # samples[i] =  np.expand_dims(samples[i][1:], axis=0)\n",
    "print(sample[:1])"
   ]
  },
  {
   "cell_type": "markdown",
   "id": "b7c35199-600c-4a61-9ed3-df2c2b44125e",
   "metadata": {},
   "source": [
    "# Testing Realtime Detection"
   ]
  },
  {
   "cell_type": "code",
   "execution_count": null,
   "id": "d2349ca2-d2e2-4099-89d6-52b3f60ce9e5",
   "metadata": {
    "scrolled": true
   },
   "outputs": [
    {
     "name": "stdout",
     "output_type": "stream",
     "text": [
      "Inference error: Graph execution error:\n",
      "\n",
      "Detected at node 'model/landmarks_detector_v3/map/while/PyFunc' defined at (most recent call last):\n",
      "Node: 'model/landmarks_detector_v3/map/while/PyFunc'\n",
      "ValueError: Could not find callback with key=pyfunc_13 in the registry.\n",
      "Traceback (most recent call last):\n",
      "\n",
      "  File \"D:\\Apps\\anaconda\\envs\\swara\\lib\\site-packages\\tensorflow\\python\\ops\\script_ops.py\", line 256, in __call__\n",
      "    raise ValueError(f\"Could not find callback with key={token} in the \"\n",
      "\n",
      "ValueError: Could not find callback with key=pyfunc_13 in the registry.\n",
      "\n",
      "\n",
      "\t [[{{node model/landmarks_detector_v3/map/while/PyFunc}}]] [Op:__inference_infer_788]\n",
      "Inference error: Graph execution error:\n",
      "\n",
      "Detected at node 'model/landmarks_detector_v3/map/while/PyFunc' defined at (most recent call last):\n",
      "Node: 'model/landmarks_detector_v3/map/while/PyFunc'\n",
      "ValueError: Could not find callback with key=pyfunc_13 in the registry.\n",
      "Traceback (most recent call last):\n",
      "\n",
      "  File \"D:\\Apps\\anaconda\\envs\\swara\\lib\\site-packages\\tensorflow\\python\\ops\\script_ops.py\", line 256, in __call__\n",
      "    raise ValueError(f\"Could not find callback with key={token} in the \"\n",
      "\n",
      "ValueError: Could not find callback with key=pyfunc_13 in the registry.\n",
      "\n",
      "\n",
      "\t [[{{node model/landmarks_detector_v3/map/while/PyFunc}}]] [Op:__inference_infer_788]\n",
      "Inference error: Graph execution error:\n",
      "\n",
      "Detected at node 'model/landmarks_detector_v3/map/while/PyFunc' defined at (most recent call last):\n",
      "Node: 'model/landmarks_detector_v3/map/while/PyFunc'\n",
      "ValueError: Could not find callback with key=pyfunc_13 in the registry.\n",
      "Traceback (most recent call last):\n",
      "\n",
      "  File \"D:\\Apps\\anaconda\\envs\\swara\\lib\\site-packages\\tensorflow\\python\\ops\\script_ops.py\", line 256, in __call__\n",
      "    raise ValueError(f\"Could not find callback with key={token} in the \"\n",
      "\n",
      "ValueError: Could not find callback with key=pyfunc_13 in the registry.\n",
      "\n",
      "\n",
      "\t [[{{node model/landmarks_detector_v3/map/while/PyFunc}}]] [Op:__inference_infer_788]\n",
      "Inference error: Graph execution error:\n",
      "\n",
      "Detected at node 'model/landmarks_detector_v3/map/while/PyFunc' defined at (most recent call last):\n",
      "Node: 'model/landmarks_detector_v3/map/while/PyFunc'\n",
      "ValueError: Could not find callback with key=pyfunc_13 in the registry.\n",
      "Traceback (most recent call last):\n",
      "\n",
      "  File \"D:\\Apps\\anaconda\\envs\\swara\\lib\\site-packages\\tensorflow\\python\\ops\\script_ops.py\", line 256, in __call__\n",
      "    raise ValueError(f\"Could not find callback with key={token} in the \"\n",
      "\n",
      "ValueError: Could not find callback with key=pyfunc_13 in the registry.\n",
      "\n",
      "\n",
      "\t [[{{node model/landmarks_detector_v3/map/while/PyFunc}}]] [Op:__inference_infer_788]\n",
      "Inference error: Graph execution error:\n",
      "\n",
      "Detected at node 'model/landmarks_detector_v3/map/while/PyFunc' defined at (most recent call last):\n",
      "Node: 'model/landmarks_detector_v3/map/while/PyFunc'\n",
      "ValueError: Could not find callback with key=pyfunc_13 in the registry.\n",
      "Traceback (most recent call last):\n",
      "\n",
      "  File \"D:\\Apps\\anaconda\\envs\\swara\\lib\\site-packages\\tensorflow\\python\\ops\\script_ops.py\", line 256, in __call__\n",
      "    raise ValueError(f\"Could not find callback with key={token} in the \"\n",
      "\n",
      "ValueError: Could not find callback with key=pyfunc_13 in the registry.\n",
      "\n",
      "\n",
      "\t [[{{node model/landmarks_detector_v3/map/while/PyFunc}}]] [Op:__inference_infer_788]\n",
      "Inference error: Graph execution error:\n",
      "\n",
      "Detected at node 'model/landmarks_detector_v3/map/while/PyFunc' defined at (most recent call last):\n",
      "Node: 'model/landmarks_detector_v3/map/while/PyFunc'\n",
      "ValueError: Could not find callback with key=pyfunc_13 in the registry.\n",
      "Traceback (most recent call last):\n",
      "\n",
      "  File \"D:\\Apps\\anaconda\\envs\\swara\\lib\\site-packages\\tensorflow\\python\\ops\\script_ops.py\", line 256, in __call__\n",
      "    raise ValueError(f\"Could not find callback with key={token} in the \"\n",
      "\n",
      "ValueError: Could not find callback with key=pyfunc_13 in the registry.\n",
      "\n",
      "\n",
      "\t [[{{node model/landmarks_detector_v3/map/while/PyFunc}}]] [Op:__inference_infer_788]\n",
      "Inference error: Graph execution error:\n",
      "\n",
      "Detected at node 'model/landmarks_detector_v3/map/while/PyFunc' defined at (most recent call last):\n",
      "Node: 'model/landmarks_detector_v3/map/while/PyFunc'\n",
      "ValueError: Could not find callback with key=pyfunc_13 in the registry.\n",
      "Traceback (most recent call last):\n",
      "\n",
      "  File \"D:\\Apps\\anaconda\\envs\\swara\\lib\\site-packages\\tensorflow\\python\\ops\\script_ops.py\", line 256, in __call__\n",
      "    raise ValueError(f\"Could not find callback with key={token} in the \"\n",
      "\n",
      "ValueError: Could not find callback with key=pyfunc_13 in the registry.\n",
      "\n",
      "\n",
      "\t [[{{node model/landmarks_detector_v3/map/while/PyFunc}}]] [Op:__inference_infer_788]\n",
      "Inference error: Graph execution error:\n",
      "\n",
      "Detected at node 'model/landmarks_detector_v3/map/while/PyFunc' defined at (most recent call last):\n",
      "Node: 'model/landmarks_detector_v3/map/while/PyFunc'\n",
      "ValueError: Could not find callback with key=pyfunc_13 in the registry.\n",
      "Traceback (most recent call last):\n",
      "\n",
      "  File \"D:\\Apps\\anaconda\\envs\\swara\\lib\\site-packages\\tensorflow\\python\\ops\\script_ops.py\", line 256, in __call__\n",
      "    raise ValueError(f\"Could not find callback with key={token} in the \"\n",
      "\n",
      "ValueError: Could not find callback with key=pyfunc_13 in the registry.\n",
      "\n",
      "\n",
      "\t [[{{node model/landmarks_detector_v3/map/while/PyFunc}}]] [Op:__inference_infer_788]\n",
      "Inference error: Graph execution error:\n",
      "\n",
      "Detected at node 'model/landmarks_detector_v3/map/while/PyFunc' defined at (most recent call last):\n",
      "Node: 'model/landmarks_detector_v3/map/while/PyFunc'\n",
      "ValueError: Could not find callback with key=pyfunc_13 in the registry.\n",
      "Traceback (most recent call last):\n",
      "\n",
      "  File \"D:\\Apps\\anaconda\\envs\\swara\\lib\\site-packages\\tensorflow\\python\\ops\\script_ops.py\", line 256, in __call__\n",
      "    raise ValueError(f\"Could not find callback with key={token} in the \"\n",
      "\n",
      "ValueError: Could not find callback with key=pyfunc_13 in the registry.\n",
      "\n",
      "\n",
      "\t [[{{node model/landmarks_detector_v3/map/while/PyFunc}}]] [Op:__inference_infer_788]\n",
      "Inference error: Graph execution error:\n",
      "\n",
      "Detected at node 'model/landmarks_detector_v3/map/while/PyFunc' defined at (most recent call last):\n",
      "Node: 'model/landmarks_detector_v3/map/while/PyFunc'\n",
      "ValueError: Could not find callback with key=pyfunc_13 in the registry.\n",
      "Traceback (most recent call last):\n",
      "\n",
      "  File \"D:\\Apps\\anaconda\\envs\\swara\\lib\\site-packages\\tensorflow\\python\\ops\\script_ops.py\", line 256, in __call__\n",
      "    raise ValueError(f\"Could not find callback with key={token} in the \"\n",
      "\n",
      "ValueError: Could not find callback with key=pyfunc_13 in the registry.\n",
      "\n",
      "\n",
      "\t [[{{node model/landmarks_detector_v3/map/while/PyFunc}}]] [Op:__inference_infer_788]\n",
      "Inference error: Graph execution error:\n",
      "\n",
      "Detected at node 'model/landmarks_detector_v3/map/while/PyFunc' defined at (most recent call last):\n",
      "Node: 'model/landmarks_detector_v3/map/while/PyFunc'\n",
      "ValueError: Could not find callback with key=pyfunc_13 in the registry.\n",
      "Traceback (most recent call last):\n",
      "\n",
      "  File \"D:\\Apps\\anaconda\\envs\\swara\\lib\\site-packages\\tensorflow\\python\\ops\\script_ops.py\", line 256, in __call__\n",
      "    raise ValueError(f\"Could not find callback with key={token} in the \"\n",
      "\n",
      "ValueError: Could not find callback with key=pyfunc_13 in the registry.\n",
      "\n",
      "\n",
      "\t [[{{node model/landmarks_detector_v3/map/while/PyFunc}}]] [Op:__inference_infer_788]\n",
      "Inference error: Graph execution error:\n",
      "\n",
      "Detected at node 'model/landmarks_detector_v3/map/while/PyFunc' defined at (most recent call last):\n",
      "Node: 'model/landmarks_detector_v3/map/while/PyFunc'\n",
      "ValueError: Could not find callback with key=pyfunc_13 in the registry.\n",
      "Traceback (most recent call last):\n",
      "\n",
      "  File \"D:\\Apps\\anaconda\\envs\\swara\\lib\\site-packages\\tensorflow\\python\\ops\\script_ops.py\", line 256, in __call__\n",
      "    raise ValueError(f\"Could not find callback with key={token} in the \"\n",
      "\n",
      "ValueError: Could not find callback with key=pyfunc_13 in the registry.\n",
      "\n",
      "\n",
      "\t [[{{node model/landmarks_detector_v3/map/while/PyFunc}}]] [Op:__inference_infer_788]\n",
      "Inference error: Graph execution error:\n",
      "\n",
      "Detected at node 'model/landmarks_detector_v3/map/while/PyFunc' defined at (most recent call last):\n",
      "Node: 'model/landmarks_detector_v3/map/while/PyFunc'\n",
      "ValueError: Could not find callback with key=pyfunc_13 in the registry.\n",
      "Traceback (most recent call last):\n",
      "\n",
      "  File \"D:\\Apps\\anaconda\\envs\\swara\\lib\\site-packages\\tensorflow\\python\\ops\\script_ops.py\", line 256, in __call__\n",
      "    raise ValueError(f\"Could not find callback with key={token} in the \"\n",
      "\n",
      "ValueError: Could not find callback with key=pyfunc_13 in the registry.\n",
      "\n",
      "\n",
      "\t [[{{node model/landmarks_detector_v3/map/while/PyFunc}}]] [Op:__inference_infer_788]\n",
      "Inference error: Graph execution error:\n",
      "\n",
      "Detected at node 'model/landmarks_detector_v3/map/while/PyFunc' defined at (most recent call last):\n",
      "Node: 'model/landmarks_detector_v3/map/while/PyFunc'\n",
      "ValueError: Could not find callback with key=pyfunc_13 in the registry.\n",
      "Traceback (most recent call last):\n",
      "\n",
      "  File \"D:\\Apps\\anaconda\\envs\\swara\\lib\\site-packages\\tensorflow\\python\\ops\\script_ops.py\", line 256, in __call__\n",
      "    raise ValueError(f\"Could not find callback with key={token} in the \"\n",
      "\n",
      "ValueError: Could not find callback with key=pyfunc_13 in the registry.\n",
      "\n",
      "\n",
      "\t [[{{node model/landmarks_detector_v3/map/while/PyFunc}}]] [Op:__inference_infer_788]\n",
      "Inference error: Graph execution error:\n",
      "\n",
      "Detected at node 'model/landmarks_detector_v3/map/while/PyFunc' defined at (most recent call last):\n",
      "Node: 'model/landmarks_detector_v3/map/while/PyFunc'\n",
      "ValueError: Could not find callback with key=pyfunc_13 in the registry.\n",
      "Traceback (most recent call last):\n",
      "\n",
      "  File \"D:\\Apps\\anaconda\\envs\\swara\\lib\\site-packages\\tensorflow\\python\\ops\\script_ops.py\", line 256, in __call__\n",
      "    raise ValueError(f\"Could not find callback with key={token} in the \"\n",
      "\n",
      "ValueError: Could not find callback with key=pyfunc_13 in the registry.\n",
      "\n",
      "\n",
      "\t [[{{node model/landmarks_detector_v3/map/while/PyFunc}}]] [Op:__inference_infer_788]\n",
      "Inference error: Graph execution error:\n",
      "\n",
      "Detected at node 'model/landmarks_detector_v3/map/while/PyFunc' defined at (most recent call last):\n",
      "Node: 'model/landmarks_detector_v3/map/while/PyFunc'\n",
      "ValueError: Could not find callback with key=pyfunc_13 in the registry.\n",
      "Traceback (most recent call last):\n",
      "\n",
      "  File \"D:\\Apps\\anaconda\\envs\\swara\\lib\\site-packages\\tensorflow\\python\\ops\\script_ops.py\", line 256, in __call__\n",
      "    raise ValueError(f\"Could not find callback with key={token} in the \"\n",
      "\n",
      "ValueError: Could not find callback with key=pyfunc_13 in the registry.\n",
      "\n",
      "\n",
      "\t [[{{node model/landmarks_detector_v3/map/while/PyFunc}}]] [Op:__inference_infer_788]\n",
      "Inference error: Graph execution error:\n",
      "\n",
      "Detected at node 'model/landmarks_detector_v3/map/while/PyFunc' defined at (most recent call last):\n",
      "Node: 'model/landmarks_detector_v3/map/while/PyFunc'\n",
      "ValueError: Could not find callback with key=pyfunc_13 in the registry.\n",
      "Traceback (most recent call last):\n",
      "\n",
      "  File \"D:\\Apps\\anaconda\\envs\\swara\\lib\\site-packages\\tensorflow\\python\\ops\\script_ops.py\", line 256, in __call__\n",
      "    raise ValueError(f\"Could not find callback with key={token} in the \"\n",
      "\n",
      "ValueError: Could not find callback with key=pyfunc_13 in the registry.\n",
      "\n",
      "\n",
      "\t [[{{node model/landmarks_detector_v3/map/while/PyFunc}}]] [Op:__inference_infer_788]\n",
      "Inference error: Graph execution error:\n",
      "\n",
      "Detected at node 'model/landmarks_detector_v3/map/while/PyFunc' defined at (most recent call last):\n",
      "Node: 'model/landmarks_detector_v3/map/while/PyFunc'\n",
      "ValueError: Could not find callback with key=pyfunc_13 in the registry.\n",
      "Traceback (most recent call last):\n",
      "\n",
      "  File \"D:\\Apps\\anaconda\\envs\\swara\\lib\\site-packages\\tensorflow\\python\\ops\\script_ops.py\", line 256, in __call__\n",
      "    raise ValueError(f\"Could not find callback with key={token} in the \"\n",
      "\n",
      "ValueError: Could not find callback with key=pyfunc_13 in the registry.\n",
      "\n",
      "\n",
      "\t [[{{node model/landmarks_detector_v3/map/while/PyFunc}}]] [Op:__inference_infer_788]\n",
      "Inference error: Graph execution error:\n",
      "\n",
      "Detected at node 'model/landmarks_detector_v3/map/while/PyFunc' defined at (most recent call last):\n",
      "Node: 'model/landmarks_detector_v3/map/while/PyFunc'\n",
      "ValueError: Could not find callback with key=pyfunc_13 in the registry.\n",
      "Traceback (most recent call last):\n",
      "\n",
      "  File \"D:\\Apps\\anaconda\\envs\\swara\\lib\\site-packages\\tensorflow\\python\\ops\\script_ops.py\", line 256, in __call__\n",
      "    raise ValueError(f\"Could not find callback with key={token} in the \"\n",
      "\n",
      "ValueError: Could not find callback with key=pyfunc_13 in the registry.\n",
      "\n",
      "\n",
      "\t [[{{node model/landmarks_detector_v3/map/while/PyFunc}}]] [Op:__inference_infer_788]\n",
      "Inference error: Graph execution error:\n",
      "\n",
      "Detected at node 'model/landmarks_detector_v3/map/while/PyFunc' defined at (most recent call last):\n",
      "Node: 'model/landmarks_detector_v3/map/while/PyFunc'\n",
      "ValueError: Could not find callback with key=pyfunc_13 in the registry.\n",
      "Traceback (most recent call last):\n",
      "\n",
      "  File \"D:\\Apps\\anaconda\\envs\\swara\\lib\\site-packages\\tensorflow\\python\\ops\\script_ops.py\", line 256, in __call__\n",
      "    raise ValueError(f\"Could not find callback with key={token} in the \"\n",
      "\n",
      "ValueError: Could not find callback with key=pyfunc_13 in the registry.\n",
      "\n",
      "\n",
      "\t [[{{node model/landmarks_detector_v3/map/while/PyFunc}}]] [Op:__inference_infer_788]\n",
      "Inference error: Graph execution error:\n",
      "\n",
      "Detected at node 'model/landmarks_detector_v3/map/while/PyFunc' defined at (most recent call last):\n",
      "Node: 'model/landmarks_detector_v3/map/while/PyFunc'\n",
      "ValueError: Could not find callback with key=pyfunc_13 in the registry.\n",
      "Traceback (most recent call last):\n",
      "\n",
      "  File \"D:\\Apps\\anaconda\\envs\\swara\\lib\\site-packages\\tensorflow\\python\\ops\\script_ops.py\", line 256, in __call__\n",
      "    raise ValueError(f\"Could not find callback with key={token} in the \"\n",
      "\n",
      "ValueError: Could not find callback with key=pyfunc_13 in the registry.\n",
      "\n",
      "\n",
      "\t [[{{node model/landmarks_detector_v3/map/while/PyFunc}}]] [Op:__inference_infer_788]\n",
      "Inference error: Graph execution error:\n",
      "\n",
      "Detected at node 'model/landmarks_detector_v3/map/while/PyFunc' defined at (most recent call last):\n",
      "Node: 'model/landmarks_detector_v3/map/while/PyFunc'\n",
      "ValueError: Could not find callback with key=pyfunc_13 in the registry.\n",
      "Traceback (most recent call last):\n",
      "\n",
      "  File \"D:\\Apps\\anaconda\\envs\\swara\\lib\\site-packages\\tensorflow\\python\\ops\\script_ops.py\", line 256, in __call__\n",
      "    raise ValueError(f\"Could not find callback with key={token} in the \"\n",
      "\n",
      "ValueError: Could not find callback with key=pyfunc_13 in the registry.\n",
      "\n",
      "\n",
      "\t [[{{node model/landmarks_detector_v3/map/while/PyFunc}}]] [Op:__inference_infer_788]\n",
      "Inference error: Graph execution error:\n",
      "\n",
      "Detected at node 'model/landmarks_detector_v3/map/while/PyFunc' defined at (most recent call last):\n",
      "Node: 'model/landmarks_detector_v3/map/while/PyFunc'\n",
      "ValueError: Could not find callback with key=pyfunc_13 in the registry.\n",
      "Traceback (most recent call last):\n",
      "\n",
      "  File \"D:\\Apps\\anaconda\\envs\\swara\\lib\\site-packages\\tensorflow\\python\\ops\\script_ops.py\", line 256, in __call__\n",
      "    raise ValueError(f\"Could not find callback with key={token} in the \"\n",
      "\n",
      "ValueError: Could not find callback with key=pyfunc_13 in the registry.\n",
      "\n",
      "\n",
      "\t [[{{node model/landmarks_detector_v3/map/while/PyFunc}}]] [Op:__inference_infer_788]\n",
      "Inference error: Graph execution error:\n",
      "\n",
      "Detected at node 'model/landmarks_detector_v3/map/while/PyFunc' defined at (most recent call last):\n",
      "Node: 'model/landmarks_detector_v3/map/while/PyFunc'\n",
      "ValueError: Could not find callback with key=pyfunc_13 in the registry.\n",
      "Traceback (most recent call last):\n",
      "\n",
      "  File \"D:\\Apps\\anaconda\\envs\\swara\\lib\\site-packages\\tensorflow\\python\\ops\\script_ops.py\", line 256, in __call__\n",
      "    raise ValueError(f\"Could not find callback with key={token} in the \"\n",
      "\n",
      "ValueError: Could not find callback with key=pyfunc_13 in the registry.\n",
      "\n",
      "\n",
      "\t [[{{node model/landmarks_detector_v3/map/while/PyFunc}}]] [Op:__inference_infer_788]\n",
      "Inference error: Graph execution error:\n",
      "\n",
      "Detected at node 'model/landmarks_detector_v3/map/while/PyFunc' defined at (most recent call last):\n",
      "Node: 'model/landmarks_detector_v3/map/while/PyFunc'\n",
      "ValueError: Could not find callback with key=pyfunc_13 in the registry.\n",
      "Traceback (most recent call last):\n",
      "\n",
      "  File \"D:\\Apps\\anaconda\\envs\\swara\\lib\\site-packages\\tensorflow\\python\\ops\\script_ops.py\", line 256, in __call__\n",
      "    raise ValueError(f\"Could not find callback with key={token} in the \"\n",
      "\n",
      "ValueError: Could not find callback with key=pyfunc_13 in the registry.\n",
      "\n",
      "\n",
      "\t [[{{node model/landmarks_detector_v3/map/while/PyFunc}}]] [Op:__inference_infer_788]\n",
      "Inference error: Graph execution error:\n",
      "\n",
      "Detected at node 'model/landmarks_detector_v3/map/while/PyFunc' defined at (most recent call last):\n",
      "Node: 'model/landmarks_detector_v3/map/while/PyFunc'\n",
      "ValueError: Could not find callback with key=pyfunc_13 in the registry.\n",
      "Traceback (most recent call last):\n",
      "\n",
      "  File \"D:\\Apps\\anaconda\\envs\\swara\\lib\\site-packages\\tensorflow\\python\\ops\\script_ops.py\", line 256, in __call__\n",
      "    raise ValueError(f\"Could not find callback with key={token} in the \"\n",
      "\n",
      "ValueError: Could not find callback with key=pyfunc_13 in the registry.\n",
      "\n",
      "\n",
      "\t [[{{node model/landmarks_detector_v3/map/while/PyFunc}}]] [Op:__inference_infer_788]\n",
      "Inference error: Graph execution error:\n",
      "\n",
      "Detected at node 'model/landmarks_detector_v3/map/while/PyFunc' defined at (most recent call last):\n",
      "Node: 'model/landmarks_detector_v3/map/while/PyFunc'\n",
      "ValueError: Could not find callback with key=pyfunc_13 in the registry.\n",
      "Traceback (most recent call last):\n",
      "\n",
      "  File \"D:\\Apps\\anaconda\\envs\\swara\\lib\\site-packages\\tensorflow\\python\\ops\\script_ops.py\", line 256, in __call__\n",
      "    raise ValueError(f\"Could not find callback with key={token} in the \"\n",
      "\n",
      "ValueError: Could not find callback with key=pyfunc_13 in the registry.\n",
      "\n",
      "\n",
      "\t [[{{node model/landmarks_detector_v3/map/while/PyFunc}}]] [Op:__inference_infer_788]\n",
      "Inference error: Graph execution error:\n",
      "\n",
      "Detected at node 'model/landmarks_detector_v3/map/while/PyFunc' defined at (most recent call last):\n",
      "Node: 'model/landmarks_detector_v3/map/while/PyFunc'\n",
      "ValueError: Could not find callback with key=pyfunc_13 in the registry.\n",
      "Traceback (most recent call last):\n",
      "\n",
      "  File \"D:\\Apps\\anaconda\\envs\\swara\\lib\\site-packages\\tensorflow\\python\\ops\\script_ops.py\", line 256, in __call__\n",
      "    raise ValueError(f\"Could not find callback with key={token} in the \"\n",
      "\n",
      "ValueError: Could not find callback with key=pyfunc_13 in the registry.\n",
      "\n",
      "\n",
      "\t [[{{node model/landmarks_detector_v3/map/while/PyFunc}}]] [Op:__inference_infer_788]\n",
      "Inference error: Graph execution error:\n",
      "\n",
      "Detected at node 'model/landmarks_detector_v3/map/while/PyFunc' defined at (most recent call last):\n",
      "Node: 'model/landmarks_detector_v3/map/while/PyFunc'\n",
      "ValueError: Could not find callback with key=pyfunc_13 in the registry.\n",
      "Traceback (most recent call last):\n",
      "\n",
      "  File \"D:\\Apps\\anaconda\\envs\\swara\\lib\\site-packages\\tensorflow\\python\\ops\\script_ops.py\", line 256, in __call__\n",
      "    raise ValueError(f\"Could not find callback with key={token} in the \"\n",
      "\n",
      "ValueError: Could not find callback with key=pyfunc_13 in the registry.\n",
      "\n",
      "\n",
      "\t [[{{node model/landmarks_detector_v3/map/while/PyFunc}}]] [Op:__inference_infer_788]\n",
      "Inference error: Graph execution error:\n",
      "\n",
      "Detected at node 'model/landmarks_detector_v3/map/while/PyFunc' defined at (most recent call last):\n",
      "Node: 'model/landmarks_detector_v3/map/while/PyFunc'\n",
      "ValueError: Could not find callback with key=pyfunc_13 in the registry.\n",
      "Traceback (most recent call last):\n",
      "\n",
      "  File \"D:\\Apps\\anaconda\\envs\\swara\\lib\\site-packages\\tensorflow\\python\\ops\\script_ops.py\", line 256, in __call__\n",
      "    raise ValueError(f\"Could not find callback with key={token} in the \"\n",
      "\n",
      "ValueError: Could not find callback with key=pyfunc_13 in the registry.\n",
      "\n",
      "\n",
      "\t [[{{node model/landmarks_detector_v3/map/while/PyFunc}}]] [Op:__inference_infer_788]\n",
      "Inference error: Graph execution error:\n",
      "\n",
      "Detected at node 'model/landmarks_detector_v3/map/while/PyFunc' defined at (most recent call last):\n",
      "Node: 'model/landmarks_detector_v3/map/while/PyFunc'\n",
      "ValueError: Could not find callback with key=pyfunc_13 in the registry.\n",
      "Traceback (most recent call last):\n",
      "\n",
      "  File \"D:\\Apps\\anaconda\\envs\\swara\\lib\\site-packages\\tensorflow\\python\\ops\\script_ops.py\", line 256, in __call__\n",
      "    raise ValueError(f\"Could not find callback with key={token} in the \"\n",
      "\n",
      "ValueError: Could not find callback with key=pyfunc_13 in the registry.\n",
      "\n",
      "\n",
      "\t [[{{node model/landmarks_detector_v3/map/while/PyFunc}}]] [Op:__inference_infer_788]\n",
      "Inference error: Graph execution error:\n",
      "\n",
      "Detected at node 'model/landmarks_detector_v3/map/while/PyFunc' defined at (most recent call last):\n",
      "Node: 'model/landmarks_detector_v3/map/while/PyFunc'\n",
      "ValueError: Could not find callback with key=pyfunc_13 in the registry.\n",
      "Traceback (most recent call last):\n",
      "\n",
      "  File \"D:\\Apps\\anaconda\\envs\\swara\\lib\\site-packages\\tensorflow\\python\\ops\\script_ops.py\", line 256, in __call__\n",
      "    raise ValueError(f\"Could not find callback with key={token} in the \"\n",
      "\n",
      "ValueError: Could not find callback with key=pyfunc_13 in the registry.\n",
      "\n",
      "\n",
      "\t [[{{node model/landmarks_detector_v3/map/while/PyFunc}}]] [Op:__inference_infer_788]\n",
      "Inference error: Graph execution error:\n",
      "\n",
      "Detected at node 'model/landmarks_detector_v3/map/while/PyFunc' defined at (most recent call last):\n",
      "Node: 'model/landmarks_detector_v3/map/while/PyFunc'\n",
      "ValueError: Could not find callback with key=pyfunc_13 in the registry.\n",
      "Traceback (most recent call last):\n",
      "\n",
      "  File \"D:\\Apps\\anaconda\\envs\\swara\\lib\\site-packages\\tensorflow\\python\\ops\\script_ops.py\", line 256, in __call__\n",
      "    raise ValueError(f\"Could not find callback with key={token} in the \"\n",
      "\n",
      "ValueError: Could not find callback with key=pyfunc_13 in the registry.\n",
      "\n",
      "\n",
      "\t [[{{node model/landmarks_detector_v3/map/while/PyFunc}}]] [Op:__inference_infer_788]\n",
      "Inference error: Graph execution error:\n",
      "\n",
      "Detected at node 'model/landmarks_detector_v3/map/while/PyFunc' defined at (most recent call last):\n",
      "Node: 'model/landmarks_detector_v3/map/while/PyFunc'\n",
      "ValueError: Could not find callback with key=pyfunc_13 in the registry.\n",
      "Traceback (most recent call last):\n",
      "\n",
      "  File \"D:\\Apps\\anaconda\\envs\\swara\\lib\\site-packages\\tensorflow\\python\\ops\\script_ops.py\", line 256, in __call__\n",
      "    raise ValueError(f\"Could not find callback with key={token} in the \"\n",
      "\n",
      "ValueError: Could not find callback with key=pyfunc_13 in the registry.\n",
      "\n",
      "\n",
      "\t [[{{node model/landmarks_detector_v3/map/while/PyFunc}}]] [Op:__inference_infer_788]\n",
      "Inference error: Graph execution error:\n",
      "\n",
      "Detected at node 'model/landmarks_detector_v3/map/while/PyFunc' defined at (most recent call last):\n",
      "Node: 'model/landmarks_detector_v3/map/while/PyFunc'\n",
      "ValueError: Could not find callback with key=pyfunc_13 in the registry.\n",
      "Traceback (most recent call last):\n",
      "\n",
      "  File \"D:\\Apps\\anaconda\\envs\\swara\\lib\\site-packages\\tensorflow\\python\\ops\\script_ops.py\", line 256, in __call__\n",
      "    raise ValueError(f\"Could not find callback with key={token} in the \"\n",
      "\n",
      "ValueError: Could not find callback with key=pyfunc_13 in the registry.\n",
      "\n",
      "\n",
      "\t [[{{node model/landmarks_detector_v3/map/while/PyFunc}}]] [Op:__inference_infer_788]\n",
      "Inference error: Graph execution error:\n",
      "\n",
      "Detected at node 'model/landmarks_detector_v3/map/while/PyFunc' defined at (most recent call last):\n",
      "Node: 'model/landmarks_detector_v3/map/while/PyFunc'\n",
      "ValueError: Could not find callback with key=pyfunc_13 in the registry.\n",
      "Traceback (most recent call last):\n",
      "\n",
      "  File \"D:\\Apps\\anaconda\\envs\\swara\\lib\\site-packages\\tensorflow\\python\\ops\\script_ops.py\", line 256, in __call__\n",
      "    raise ValueError(f\"Could not find callback with key={token} in the \"\n",
      "\n",
      "ValueError: Could not find callback with key=pyfunc_13 in the registry.\n",
      "\n",
      "\n",
      "\t [[{{node model/landmarks_detector_v3/map/while/PyFunc}}]] [Op:__inference_infer_788]\n",
      "Inference error: Graph execution error:\n",
      "\n",
      "Detected at node 'model/landmarks_detector_v3/map/while/PyFunc' defined at (most recent call last):\n",
      "Node: 'model/landmarks_detector_v3/map/while/PyFunc'\n",
      "ValueError: Could not find callback with key=pyfunc_13 in the registry.\n",
      "Traceback (most recent call last):\n",
      "\n",
      "  File \"D:\\Apps\\anaconda\\envs\\swara\\lib\\site-packages\\tensorflow\\python\\ops\\script_ops.py\", line 256, in __call__\n",
      "    raise ValueError(f\"Could not find callback with key={token} in the \"\n",
      "\n",
      "ValueError: Could not find callback with key=pyfunc_13 in the registry.\n",
      "\n",
      "\n",
      "\t [[{{node model/landmarks_detector_v3/map/while/PyFunc}}]] [Op:__inference_infer_788]\n",
      "Inference error: Graph execution error:\n",
      "\n",
      "Detected at node 'model/landmarks_detector_v3/map/while/PyFunc' defined at (most recent call last):\n",
      "Node: 'model/landmarks_detector_v3/map/while/PyFunc'\n",
      "ValueError: Could not find callback with key=pyfunc_13 in the registry.\n",
      "Traceback (most recent call last):\n",
      "\n",
      "  File \"D:\\Apps\\anaconda\\envs\\swara\\lib\\site-packages\\tensorflow\\python\\ops\\script_ops.py\", line 256, in __call__\n",
      "    raise ValueError(f\"Could not find callback with key={token} in the \"\n",
      "\n",
      "ValueError: Could not find callback with key=pyfunc_13 in the registry.\n",
      "\n",
      "\n",
      "\t [[{{node model/landmarks_detector_v3/map/while/PyFunc}}]] [Op:__inference_infer_788]\n",
      "Inference error: Graph execution error:\n",
      "\n",
      "Detected at node 'model/landmarks_detector_v3/map/while/PyFunc' defined at (most recent call last):\n",
      "Node: 'model/landmarks_detector_v3/map/while/PyFunc'\n",
      "ValueError: Could not find callback with key=pyfunc_13 in the registry.\n",
      "Traceback (most recent call last):\n",
      "\n",
      "  File \"D:\\Apps\\anaconda\\envs\\swara\\lib\\site-packages\\tensorflow\\python\\ops\\script_ops.py\", line 256, in __call__\n",
      "    raise ValueError(f\"Could not find callback with key={token} in the \"\n",
      "\n",
      "ValueError: Could not find callback with key=pyfunc_13 in the registry.\n",
      "\n",
      "\n",
      "\t [[{{node model/landmarks_detector_v3/map/while/PyFunc}}]] [Op:__inference_infer_788]\n",
      "Inference error: Graph execution error:\n",
      "\n",
      "Detected at node 'model/landmarks_detector_v3/map/while/PyFunc' defined at (most recent call last):\n",
      "Node: 'model/landmarks_detector_v3/map/while/PyFunc'\n",
      "ValueError: Could not find callback with key=pyfunc_13 in the registry.\n",
      "Traceback (most recent call last):\n",
      "\n",
      "  File \"D:\\Apps\\anaconda\\envs\\swara\\lib\\site-packages\\tensorflow\\python\\ops\\script_ops.py\", line 256, in __call__\n",
      "    raise ValueError(f\"Could not find callback with key={token} in the \"\n",
      "\n",
      "ValueError: Could not find callback with key=pyfunc_13 in the registry.\n",
      "\n",
      "\n",
      "\t [[{{node model/landmarks_detector_v3/map/while/PyFunc}}]] [Op:__inference_infer_788]\n",
      "Inference error: Graph execution error:\n",
      "\n",
      "Detected at node 'model/landmarks_detector_v3/map/while/PyFunc' defined at (most recent call last):\n",
      "Node: 'model/landmarks_detector_v3/map/while/PyFunc'\n",
      "ValueError: Could not find callback with key=pyfunc_13 in the registry.\n",
      "Traceback (most recent call last):\n",
      "\n",
      "  File \"D:\\Apps\\anaconda\\envs\\swara\\lib\\site-packages\\tensorflow\\python\\ops\\script_ops.py\", line 256, in __call__\n",
      "    raise ValueError(f\"Could not find callback with key={token} in the \"\n",
      "\n",
      "ValueError: Could not find callback with key=pyfunc_13 in the registry.\n",
      "\n",
      "\n",
      "\t [[{{node model/landmarks_detector_v3/map/while/PyFunc}}]] [Op:__inference_infer_788]\n",
      "Inference error: Graph execution error:\n",
      "\n",
      "Detected at node 'model/landmarks_detector_v3/map/while/PyFunc' defined at (most recent call last):\n",
      "Node: 'model/landmarks_detector_v3/map/while/PyFunc'\n",
      "ValueError: Could not find callback with key=pyfunc_13 in the registry.\n",
      "Traceback (most recent call last):\n",
      "\n",
      "  File \"D:\\Apps\\anaconda\\envs\\swara\\lib\\site-packages\\tensorflow\\python\\ops\\script_ops.py\", line 256, in __call__\n",
      "    raise ValueError(f\"Could not find callback with key={token} in the \"\n",
      "\n",
      "ValueError: Could not find callback with key=pyfunc_13 in the registry.\n",
      "\n",
      "\n",
      "\t [[{{node model/landmarks_detector_v3/map/while/PyFunc}}]] [Op:__inference_infer_788]\n",
      "Inference error: Graph execution error:\n",
      "\n",
      "Detected at node 'model/landmarks_detector_v3/map/while/PyFunc' defined at (most recent call last):\n",
      "Node: 'model/landmarks_detector_v3/map/while/PyFunc'\n",
      "ValueError: Could not find callback with key=pyfunc_13 in the registry.\n",
      "Traceback (most recent call last):\n",
      "\n",
      "  File \"D:\\Apps\\anaconda\\envs\\swara\\lib\\site-packages\\tensorflow\\python\\ops\\script_ops.py\", line 256, in __call__\n",
      "    raise ValueError(f\"Could not find callback with key={token} in the \"\n",
      "\n",
      "ValueError: Could not find callback with key=pyfunc_13 in the registry.\n",
      "\n",
      "\n",
      "\t [[{{node model/landmarks_detector_v3/map/while/PyFunc}}]] [Op:__inference_infer_788]\n",
      "Inference error: Graph execution error:\n",
      "\n",
      "Detected at node 'model/landmarks_detector_v3/map/while/PyFunc' defined at (most recent call last):\n",
      "Node: 'model/landmarks_detector_v3/map/while/PyFunc'\n",
      "ValueError: Could not find callback with key=pyfunc_13 in the registry.\n",
      "Traceback (most recent call last):\n",
      "\n",
      "  File \"D:\\Apps\\anaconda\\envs\\swara\\lib\\site-packages\\tensorflow\\python\\ops\\script_ops.py\", line 256, in __call__\n",
      "    raise ValueError(f\"Could not find callback with key={token} in the \"\n",
      "\n",
      "ValueError: Could not find callback with key=pyfunc_13 in the registry.\n",
      "\n",
      "\n",
      "\t [[{{node model/landmarks_detector_v3/map/while/PyFunc}}]] [Op:__inference_infer_788]\n",
      "Inference error: Graph execution error:\n",
      "\n",
      "Detected at node 'model/landmarks_detector_v3/map/while/PyFunc' defined at (most recent call last):\n",
      "Node: 'model/landmarks_detector_v3/map/while/PyFunc'\n",
      "ValueError: Could not find callback with key=pyfunc_13 in the registry.\n",
      "Traceback (most recent call last):\n",
      "\n",
      "  File \"D:\\Apps\\anaconda\\envs\\swara\\lib\\site-packages\\tensorflow\\python\\ops\\script_ops.py\", line 256, in __call__\n",
      "    raise ValueError(f\"Could not find callback with key={token} in the \"\n",
      "\n",
      "ValueError: Could not find callback with key=pyfunc_13 in the registry.\n",
      "\n",
      "\n",
      "\t [[{{node model/landmarks_detector_v3/map/while/PyFunc}}]] [Op:__inference_infer_788]\n",
      "Inference error: Graph execution error:\n",
      "\n",
      "Detected at node 'model/landmarks_detector_v3/map/while/PyFunc' defined at (most recent call last):\n",
      "Node: 'model/landmarks_detector_v3/map/while/PyFunc'\n",
      "ValueError: Could not find callback with key=pyfunc_13 in the registry.\n",
      "Traceback (most recent call last):\n",
      "\n",
      "  File \"D:\\Apps\\anaconda\\envs\\swara\\lib\\site-packages\\tensorflow\\python\\ops\\script_ops.py\", line 256, in __call__\n",
      "    raise ValueError(f\"Could not find callback with key={token} in the \"\n",
      "\n",
      "ValueError: Could not find callback with key=pyfunc_13 in the registry.\n",
      "\n",
      "\n",
      "\t [[{{node model/landmarks_detector_v3/map/while/PyFunc}}]] [Op:__inference_infer_788]\n",
      "Inference error: Graph execution error:\n",
      "\n",
      "Detected at node 'model/landmarks_detector_v3/map/while/PyFunc' defined at (most recent call last):\n",
      "Node: 'model/landmarks_detector_v3/map/while/PyFunc'\n",
      "ValueError: Could not find callback with key=pyfunc_13 in the registry.\n",
      "Traceback (most recent call last):\n",
      "\n",
      "  File \"D:\\Apps\\anaconda\\envs\\swara\\lib\\site-packages\\tensorflow\\python\\ops\\script_ops.py\", line 256, in __call__\n",
      "    raise ValueError(f\"Could not find callback with key={token} in the \"\n",
      "\n",
      "ValueError: Could not find callback with key=pyfunc_13 in the registry.\n",
      "\n",
      "\n",
      "\t [[{{node model/landmarks_detector_v3/map/while/PyFunc}}]] [Op:__inference_infer_788]\n",
      "Inference error: Graph execution error:\n",
      "\n",
      "Detected at node 'model/landmarks_detector_v3/map/while/PyFunc' defined at (most recent call last):\n",
      "Node: 'model/landmarks_detector_v3/map/while/PyFunc'\n",
      "ValueError: Could not find callback with key=pyfunc_13 in the registry.\n",
      "Traceback (most recent call last):\n",
      "\n",
      "  File \"D:\\Apps\\anaconda\\envs\\swara\\lib\\site-packages\\tensorflow\\python\\ops\\script_ops.py\", line 256, in __call__\n",
      "    raise ValueError(f\"Could not find callback with key={token} in the \"\n",
      "\n",
      "ValueError: Could not find callback with key=pyfunc_13 in the registry.\n",
      "\n",
      "\n",
      "\t [[{{node model/landmarks_detector_v3/map/while/PyFunc}}]] [Op:__inference_infer_788]\n",
      "Inference error: Graph execution error:\n",
      "\n",
      "Detected at node 'model/landmarks_detector_v3/map/while/PyFunc' defined at (most recent call last):\n",
      "Node: 'model/landmarks_detector_v3/map/while/PyFunc'\n",
      "ValueError: Could not find callback with key=pyfunc_13 in the registry.\n",
      "Traceback (most recent call last):\n",
      "\n",
      "  File \"D:\\Apps\\anaconda\\envs\\swara\\lib\\site-packages\\tensorflow\\python\\ops\\script_ops.py\", line 256, in __call__\n",
      "    raise ValueError(f\"Could not find callback with key={token} in the \"\n",
      "\n",
      "ValueError: Could not find callback with key=pyfunc_13 in the registry.\n",
      "\n",
      "\n",
      "\t [[{{node model/landmarks_detector_v3/map/while/PyFunc}}]] [Op:__inference_infer_788]\n",
      "Inference error: Graph execution error:\n",
      "\n",
      "Detected at node 'model/landmarks_detector_v3/map/while/PyFunc' defined at (most recent call last):\n",
      "Node: 'model/landmarks_detector_v3/map/while/PyFunc'\n",
      "ValueError: Could not find callback with key=pyfunc_13 in the registry.\n",
      "Traceback (most recent call last):\n",
      "\n",
      "  File \"D:\\Apps\\anaconda\\envs\\swara\\lib\\site-packages\\tensorflow\\python\\ops\\script_ops.py\", line 256, in __call__\n",
      "    raise ValueError(f\"Could not find callback with key={token} in the \"\n",
      "\n",
      "ValueError: Could not find callback with key=pyfunc_13 in the registry.\n",
      "\n",
      "\n",
      "\t [[{{node model/landmarks_detector_v3/map/while/PyFunc}}]] [Op:__inference_infer_788]\n",
      "Inference error: Graph execution error:\n",
      "\n",
      "Detected at node 'model/landmarks_detector_v3/map/while/PyFunc' defined at (most recent call last):\n",
      "Node: 'model/landmarks_detector_v3/map/while/PyFunc'\n",
      "ValueError: Could not find callback with key=pyfunc_13 in the registry.\n",
      "Traceback (most recent call last):\n",
      "\n",
      "  File \"D:\\Apps\\anaconda\\envs\\swara\\lib\\site-packages\\tensorflow\\python\\ops\\script_ops.py\", line 256, in __call__\n",
      "    raise ValueError(f\"Could not find callback with key={token} in the \"\n",
      "\n",
      "ValueError: Could not find callback with key=pyfunc_13 in the registry.\n",
      "\n",
      "\n",
      "\t [[{{node model/landmarks_detector_v3/map/while/PyFunc}}]] [Op:__inference_infer_788]\n",
      "Inference error: Graph execution error:\n",
      "\n",
      "Detected at node 'model/landmarks_detector_v3/map/while/PyFunc' defined at (most recent call last):\n",
      "Node: 'model/landmarks_detector_v3/map/while/PyFunc'\n",
      "ValueError: Could not find callback with key=pyfunc_13 in the registry.\n",
      "Traceback (most recent call last):\n",
      "\n",
      "  File \"D:\\Apps\\anaconda\\envs\\swara\\lib\\site-packages\\tensorflow\\python\\ops\\script_ops.py\", line 256, in __call__\n",
      "    raise ValueError(f\"Could not find callback with key={token} in the \"\n",
      "\n",
      "ValueError: Could not find callback with key=pyfunc_13 in the registry.\n",
      "\n",
      "\n",
      "\t [[{{node model/landmarks_detector_v3/map/while/PyFunc}}]] [Op:__inference_infer_788]\n",
      "Inference error: Graph execution error:\n",
      "\n",
      "Detected at node 'model/landmarks_detector_v3/map/while/PyFunc' defined at (most recent call last):\n",
      "Node: 'model/landmarks_detector_v3/map/while/PyFunc'\n",
      "ValueError: Could not find callback with key=pyfunc_13 in the registry.\n",
      "Traceback (most recent call last):\n",
      "\n",
      "  File \"D:\\Apps\\anaconda\\envs\\swara\\lib\\site-packages\\tensorflow\\python\\ops\\script_ops.py\", line 256, in __call__\n",
      "    raise ValueError(f\"Could not find callback with key={token} in the \"\n",
      "\n",
      "ValueError: Could not find callback with key=pyfunc_13 in the registry.\n",
      "\n",
      "\n",
      "\t [[{{node model/landmarks_detector_v3/map/while/PyFunc}}]] [Op:__inference_infer_788]\n",
      "Inference error: Graph execution error:\n",
      "\n",
      "Detected at node 'model/landmarks_detector_v3/map/while/PyFunc' defined at (most recent call last):\n",
      "Node: 'model/landmarks_detector_v3/map/while/PyFunc'\n",
      "ValueError: Could not find callback with key=pyfunc_13 in the registry.\n",
      "Traceback (most recent call last):\n",
      "\n",
      "  File \"D:\\Apps\\anaconda\\envs\\swara\\lib\\site-packages\\tensorflow\\python\\ops\\script_ops.py\", line 256, in __call__\n",
      "    raise ValueError(f\"Could not find callback with key={token} in the \"\n",
      "\n",
      "ValueError: Could not find callback with key=pyfunc_13 in the registry.\n",
      "\n",
      "\n",
      "\t [[{{node model/landmarks_detector_v3/map/while/PyFunc}}]] [Op:__inference_infer_788]\n",
      "Inference error: Graph execution error:\n",
      "\n",
      "Detected at node 'model/landmarks_detector_v3/map/while/PyFunc' defined at (most recent call last):\n",
      "Node: 'model/landmarks_detector_v3/map/while/PyFunc'\n",
      "ValueError: Could not find callback with key=pyfunc_13 in the registry.\n",
      "Traceback (most recent call last):\n",
      "\n",
      "  File \"D:\\Apps\\anaconda\\envs\\swara\\lib\\site-packages\\tensorflow\\python\\ops\\script_ops.py\", line 256, in __call__\n",
      "    raise ValueError(f\"Could not find callback with key={token} in the \"\n",
      "\n",
      "ValueError: Could not find callback with key=pyfunc_13 in the registry.\n",
      "\n",
      "\n",
      "\t [[{{node model/landmarks_detector_v3/map/while/PyFunc}}]] [Op:__inference_infer_788]\n",
      "Inference error: Graph execution error:\n",
      "\n",
      "Detected at node 'model/landmarks_detector_v3/map/while/PyFunc' defined at (most recent call last):\n",
      "Node: 'model/landmarks_detector_v3/map/while/PyFunc'\n",
      "ValueError: Could not find callback with key=pyfunc_13 in the registry.\n",
      "Traceback (most recent call last):\n",
      "\n",
      "  File \"D:\\Apps\\anaconda\\envs\\swara\\lib\\site-packages\\tensorflow\\python\\ops\\script_ops.py\", line 256, in __call__\n",
      "    raise ValueError(f\"Could not find callback with key={token} in the \"\n",
      "\n",
      "ValueError: Could not find callback with key=pyfunc_13 in the registry.\n",
      "\n",
      "\n",
      "\t [[{{node model/landmarks_detector_v3/map/while/PyFunc}}]] [Op:__inference_infer_788]\n",
      "Inference error: Graph execution error:\n",
      "\n",
      "Detected at node 'model/landmarks_detector_v3/map/while/PyFunc' defined at (most recent call last):\n",
      "Node: 'model/landmarks_detector_v3/map/while/PyFunc'\n",
      "ValueError: Could not find callback with key=pyfunc_13 in the registry.\n",
      "Traceback (most recent call last):\n",
      "\n",
      "  File \"D:\\Apps\\anaconda\\envs\\swara\\lib\\site-packages\\tensorflow\\python\\ops\\script_ops.py\", line 256, in __call__\n",
      "    raise ValueError(f\"Could not find callback with key={token} in the \"\n",
      "\n",
      "ValueError: Could not find callback with key=pyfunc_13 in the registry.\n",
      "\n",
      "\n",
      "\t [[{{node model/landmarks_detector_v3/map/while/PyFunc}}]] [Op:__inference_infer_788]\n",
      "Inference error: Graph execution error:\n",
      "\n",
      "Detected at node 'model/landmarks_detector_v3/map/while/PyFunc' defined at (most recent call last):\n",
      "Node: 'model/landmarks_detector_v3/map/while/PyFunc'\n",
      "ValueError: Could not find callback with key=pyfunc_13 in the registry.\n",
      "Traceback (most recent call last):\n",
      "\n",
      "  File \"D:\\Apps\\anaconda\\envs\\swara\\lib\\site-packages\\tensorflow\\python\\ops\\script_ops.py\", line 256, in __call__\n",
      "    raise ValueError(f\"Could not find callback with key={token} in the \"\n",
      "\n",
      "ValueError: Could not find callback with key=pyfunc_13 in the registry.\n",
      "\n",
      "\n",
      "\t [[{{node model/landmarks_detector_v3/map/while/PyFunc}}]] [Op:__inference_infer_788]\n",
      "Inference error: Graph execution error:\n",
      "\n",
      "Detected at node 'model/landmarks_detector_v3/map/while/PyFunc' defined at (most recent call last):\n",
      "Node: 'model/landmarks_detector_v3/map/while/PyFunc'\n",
      "ValueError: Could not find callback with key=pyfunc_13 in the registry.\n",
      "Traceback (most recent call last):\n",
      "\n",
      "  File \"D:\\Apps\\anaconda\\envs\\swara\\lib\\site-packages\\tensorflow\\python\\ops\\script_ops.py\", line 256, in __call__\n",
      "    raise ValueError(f\"Could not find callback with key={token} in the \"\n",
      "\n",
      "ValueError: Could not find callback with key=pyfunc_13 in the registry.\n",
      "\n",
      "\n",
      "\t [[{{node model/landmarks_detector_v3/map/while/PyFunc}}]] [Op:__inference_infer_788]\n",
      "Inference error: Graph execution error:\n",
      "\n",
      "Detected at node 'model/landmarks_detector_v3/map/while/PyFunc' defined at (most recent call last):\n",
      "Node: 'model/landmarks_detector_v3/map/while/PyFunc'\n",
      "ValueError: Could not find callback with key=pyfunc_13 in the registry.\n",
      "Traceback (most recent call last):\n",
      "\n",
      "  File \"D:\\Apps\\anaconda\\envs\\swara\\lib\\site-packages\\tensorflow\\python\\ops\\script_ops.py\", line 256, in __call__\n",
      "    raise ValueError(f\"Could not find callback with key={token} in the \"\n",
      "\n",
      "ValueError: Could not find callback with key=pyfunc_13 in the registry.\n",
      "\n",
      "\n",
      "\t [[{{node model/landmarks_detector_v3/map/while/PyFunc}}]] [Op:__inference_infer_788]\n",
      "Inference error: Graph execution error:\n",
      "\n",
      "Detected at node 'model/landmarks_detector_v3/map/while/PyFunc' defined at (most recent call last):\n",
      "Node: 'model/landmarks_detector_v3/map/while/PyFunc'\n",
      "ValueError: Could not find callback with key=pyfunc_13 in the registry.\n",
      "Traceback (most recent call last):\n",
      "\n",
      "  File \"D:\\Apps\\anaconda\\envs\\swara\\lib\\site-packages\\tensorflow\\python\\ops\\script_ops.py\", line 256, in __call__\n",
      "    raise ValueError(f\"Could not find callback with key={token} in the \"\n",
      "\n",
      "ValueError: Could not find callback with key=pyfunc_13 in the registry.\n",
      "\n",
      "\n",
      "\t [[{{node model/landmarks_detector_v3/map/while/PyFunc}}]] [Op:__inference_infer_788]\n",
      "Inference error: Graph execution error:\n",
      "\n",
      "Detected at node 'model/landmarks_detector_v3/map/while/PyFunc' defined at (most recent call last):\n",
      "Node: 'model/landmarks_detector_v3/map/while/PyFunc'\n",
      "ValueError: Could not find callback with key=pyfunc_13 in the registry.\n",
      "Traceback (most recent call last):\n",
      "\n",
      "  File \"D:\\Apps\\anaconda\\envs\\swara\\lib\\site-packages\\tensorflow\\python\\ops\\script_ops.py\", line 256, in __call__\n",
      "    raise ValueError(f\"Could not find callback with key={token} in the \"\n",
      "\n",
      "ValueError: Could not find callback with key=pyfunc_13 in the registry.\n",
      "\n",
      "\n",
      "\t [[{{node model/landmarks_detector_v3/map/while/PyFunc}}]] [Op:__inference_infer_788]\n",
      "Inference error: Graph execution error:\n",
      "\n",
      "Detected at node 'model/landmarks_detector_v3/map/while/PyFunc' defined at (most recent call last):\n",
      "Node: 'model/landmarks_detector_v3/map/while/PyFunc'\n",
      "ValueError: Could not find callback with key=pyfunc_13 in the registry.\n",
      "Traceback (most recent call last):\n",
      "\n",
      "  File \"D:\\Apps\\anaconda\\envs\\swara\\lib\\site-packages\\tensorflow\\python\\ops\\script_ops.py\", line 256, in __call__\n",
      "    raise ValueError(f\"Could not find callback with key={token} in the \"\n",
      "\n",
      "ValueError: Could not find callback with key=pyfunc_13 in the registry.\n",
      "\n",
      "\n",
      "\t [[{{node model/landmarks_detector_v3/map/while/PyFunc}}]] [Op:__inference_infer_788]\n",
      "Inference error: Graph execution error:\n",
      "\n",
      "Detected at node 'model/landmarks_detector_v3/map/while/PyFunc' defined at (most recent call last):\n",
      "Node: 'model/landmarks_detector_v3/map/while/PyFunc'\n",
      "ValueError: Could not find callback with key=pyfunc_13 in the registry.\n",
      "Traceback (most recent call last):\n",
      "\n",
      "  File \"D:\\Apps\\anaconda\\envs\\swara\\lib\\site-packages\\tensorflow\\python\\ops\\script_ops.py\", line 256, in __call__\n",
      "    raise ValueError(f\"Could not find callback with key={token} in the \"\n",
      "\n",
      "ValueError: Could not find callback with key=pyfunc_13 in the registry.\n",
      "\n",
      "\n",
      "\t [[{{node model/landmarks_detector_v3/map/while/PyFunc}}]] [Op:__inference_infer_788]\n",
      "Inference error: Graph execution error:\n",
      "\n",
      "Detected at node 'model/landmarks_detector_v3/map/while/PyFunc' defined at (most recent call last):\n",
      "Node: 'model/landmarks_detector_v3/map/while/PyFunc'\n",
      "ValueError: Could not find callback with key=pyfunc_13 in the registry.\n",
      "Traceback (most recent call last):\n",
      "\n",
      "  File \"D:\\Apps\\anaconda\\envs\\swara\\lib\\site-packages\\tensorflow\\python\\ops\\script_ops.py\", line 256, in __call__\n",
      "    raise ValueError(f\"Could not find callback with key={token} in the \"\n",
      "\n",
      "ValueError: Could not find callback with key=pyfunc_13 in the registry.\n",
      "\n",
      "\n",
      "\t [[{{node model/landmarks_detector_v3/map/while/PyFunc}}]] [Op:__inference_infer_788]\n",
      "Inference error: Graph execution error:\n",
      "\n",
      "Detected at node 'model/landmarks_detector_v3/map/while/PyFunc' defined at (most recent call last):\n",
      "Node: 'model/landmarks_detector_v3/map/while/PyFunc'\n",
      "ValueError: Could not find callback with key=pyfunc_13 in the registry.\n",
      "Traceback (most recent call last):\n",
      "\n",
      "  File \"D:\\Apps\\anaconda\\envs\\swara\\lib\\site-packages\\tensorflow\\python\\ops\\script_ops.py\", line 256, in __call__\n",
      "    raise ValueError(f\"Could not find callback with key={token} in the \"\n",
      "\n",
      "ValueError: Could not find callback with key=pyfunc_13 in the registry.\n",
      "\n",
      "\n",
      "\t [[{{node model/landmarks_detector_v3/map/while/PyFunc}}]] [Op:__inference_infer_788]\n",
      "Inference error: Graph execution error:\n",
      "\n",
      "Detected at node 'model/landmarks_detector_v3/map/while/PyFunc' defined at (most recent call last):\n",
      "Node: 'model/landmarks_detector_v3/map/while/PyFunc'\n",
      "ValueError: Could not find callback with key=pyfunc_13 in the registry.\n",
      "Traceback (most recent call last):\n",
      "\n",
      "  File \"D:\\Apps\\anaconda\\envs\\swara\\lib\\site-packages\\tensorflow\\python\\ops\\script_ops.py\", line 256, in __call__\n",
      "    raise ValueError(f\"Could not find callback with key={token} in the \"\n",
      "\n",
      "ValueError: Could not find callback with key=pyfunc_13 in the registry.\n",
      "\n",
      "\n",
      "\t [[{{node model/landmarks_detector_v3/map/while/PyFunc}}]] [Op:__inference_infer_788]\n",
      "Inference error: Graph execution error:\n",
      "\n",
      "Detected at node 'model/landmarks_detector_v3/map/while/PyFunc' defined at (most recent call last):\n",
      "Node: 'model/landmarks_detector_v3/map/while/PyFunc'\n",
      "ValueError: Could not find callback with key=pyfunc_13 in the registry.\n",
      "Traceback (most recent call last):\n",
      "\n",
      "  File \"D:\\Apps\\anaconda\\envs\\swara\\lib\\site-packages\\tensorflow\\python\\ops\\script_ops.py\", line 256, in __call__\n",
      "    raise ValueError(f\"Could not find callback with key={token} in the \"\n",
      "\n",
      "ValueError: Could not find callback with key=pyfunc_13 in the registry.\n",
      "\n",
      "\n",
      "\t [[{{node model/landmarks_detector_v3/map/while/PyFunc}}]] [Op:__inference_infer_788]\n",
      "Inference error: Graph execution error:\n",
      "\n",
      "Detected at node 'model/landmarks_detector_v3/map/while/PyFunc' defined at (most recent call last):\n",
      "Node: 'model/landmarks_detector_v3/map/while/PyFunc'\n",
      "ValueError: Could not find callback with key=pyfunc_13 in the registry.\n",
      "Traceback (most recent call last):\n",
      "\n",
      "  File \"D:\\Apps\\anaconda\\envs\\swara\\lib\\site-packages\\tensorflow\\python\\ops\\script_ops.py\", line 256, in __call__\n",
      "    raise ValueError(f\"Could not find callback with key={token} in the \"\n",
      "\n",
      "ValueError: Could not find callback with key=pyfunc_13 in the registry.\n",
      "\n",
      "\n",
      "\t [[{{node model/landmarks_detector_v3/map/while/PyFunc}}]] [Op:__inference_infer_788]\n",
      "Inference error: Graph execution error:\n",
      "\n",
      "Detected at node 'model/landmarks_detector_v3/map/while/PyFunc' defined at (most recent call last):\n",
      "Node: 'model/landmarks_detector_v3/map/while/PyFunc'\n",
      "ValueError: Could not find callback with key=pyfunc_13 in the registry.\n",
      "Traceback (most recent call last):\n",
      "\n",
      "  File \"D:\\Apps\\anaconda\\envs\\swara\\lib\\site-packages\\tensorflow\\python\\ops\\script_ops.py\", line 256, in __call__\n",
      "    raise ValueError(f\"Could not find callback with key={token} in the \"\n",
      "\n",
      "ValueError: Could not find callback with key=pyfunc_13 in the registry.\n",
      "\n",
      "\n",
      "\t [[{{node model/landmarks_detector_v3/map/while/PyFunc}}]] [Op:__inference_infer_788]\n",
      "Inference error: Graph execution error:\n",
      "\n",
      "Detected at node 'model/landmarks_detector_v3/map/while/PyFunc' defined at (most recent call last):\n",
      "Node: 'model/landmarks_detector_v3/map/while/PyFunc'\n",
      "ValueError: Could not find callback with key=pyfunc_13 in the registry.\n",
      "Traceback (most recent call last):\n",
      "\n",
      "  File \"D:\\Apps\\anaconda\\envs\\swara\\lib\\site-packages\\tensorflow\\python\\ops\\script_ops.py\", line 256, in __call__\n",
      "    raise ValueError(f\"Could not find callback with key={token} in the \"\n",
      "\n",
      "ValueError: Could not find callback with key=pyfunc_13 in the registry.\n",
      "\n",
      "\n",
      "\t [[{{node model/landmarks_detector_v3/map/while/PyFunc}}]] [Op:__inference_infer_788]\n",
      "Inference error: Graph execution error:\n",
      "\n",
      "Detected at node 'model/landmarks_detector_v3/map/while/PyFunc' defined at (most recent call last):\n",
      "Node: 'model/landmarks_detector_v3/map/while/PyFunc'\n",
      "ValueError: Could not find callback with key=pyfunc_13 in the registry.\n",
      "Traceback (most recent call last):\n",
      "\n",
      "  File \"D:\\Apps\\anaconda\\envs\\swara\\lib\\site-packages\\tensorflow\\python\\ops\\script_ops.py\", line 256, in __call__\n",
      "    raise ValueError(f\"Could not find callback with key={token} in the \"\n",
      "\n",
      "ValueError: Could not find callback with key=pyfunc_13 in the registry.\n",
      "\n",
      "\n",
      "\t [[{{node model/landmarks_detector_v3/map/while/PyFunc}}]] [Op:__inference_infer_788]\n",
      "Inference error: Graph execution error:\n",
      "\n",
      "Detected at node 'model/landmarks_detector_v3/map/while/PyFunc' defined at (most recent call last):\n",
      "Node: 'model/landmarks_detector_v3/map/while/PyFunc'\n",
      "ValueError: Could not find callback with key=pyfunc_13 in the registry.\n",
      "Traceback (most recent call last):\n",
      "\n",
      "  File \"D:\\Apps\\anaconda\\envs\\swara\\lib\\site-packages\\tensorflow\\python\\ops\\script_ops.py\", line 256, in __call__\n",
      "    raise ValueError(f\"Could not find callback with key={token} in the \"\n",
      "\n",
      "ValueError: Could not find callback with key=pyfunc_13 in the registry.\n",
      "\n",
      "\n",
      "\t [[{{node model/landmarks_detector_v3/map/while/PyFunc}}]] [Op:__inference_infer_788]\n",
      "Inference error: Graph execution error:\n",
      "\n",
      "Detected at node 'model/landmarks_detector_v3/map/while/PyFunc' defined at (most recent call last):\n",
      "Node: 'model/landmarks_detector_v3/map/while/PyFunc'\n",
      "ValueError: Could not find callback with key=pyfunc_13 in the registry.\n",
      "Traceback (most recent call last):\n",
      "\n",
      "  File \"D:\\Apps\\anaconda\\envs\\swara\\lib\\site-packages\\tensorflow\\python\\ops\\script_ops.py\", line 256, in __call__\n",
      "    raise ValueError(f\"Could not find callback with key={token} in the \"\n",
      "\n",
      "ValueError: Could not find callback with key=pyfunc_13 in the registry.\n",
      "\n",
      "\n",
      "\t [[{{node model/landmarks_detector_v3/map/while/PyFunc}}]] [Op:__inference_infer_788]\n",
      "Inference error: Graph execution error:\n",
      "\n",
      "Detected at node 'model/landmarks_detector_v3/map/while/PyFunc' defined at (most recent call last):\n",
      "Node: 'model/landmarks_detector_v3/map/while/PyFunc'\n",
      "ValueError: Could not find callback with key=pyfunc_13 in the registry.\n",
      "Traceback (most recent call last):\n",
      "\n",
      "  File \"D:\\Apps\\anaconda\\envs\\swara\\lib\\site-packages\\tensorflow\\python\\ops\\script_ops.py\", line 256, in __call__\n",
      "    raise ValueError(f\"Could not find callback with key={token} in the \"\n",
      "\n",
      "ValueError: Could not find callback with key=pyfunc_13 in the registry.\n",
      "\n",
      "\n",
      "\t [[{{node model/landmarks_detector_v3/map/while/PyFunc}}]] [Op:__inference_infer_788]\n",
      "Inference error: Graph execution error:\n",
      "\n",
      "Detected at node 'model/landmarks_detector_v3/map/while/PyFunc' defined at (most recent call last):\n",
      "Node: 'model/landmarks_detector_v3/map/while/PyFunc'\n",
      "ValueError: Could not find callback with key=pyfunc_13 in the registry.\n",
      "Traceback (most recent call last):\n",
      "\n",
      "  File \"D:\\Apps\\anaconda\\envs\\swara\\lib\\site-packages\\tensorflow\\python\\ops\\script_ops.py\", line 256, in __call__\n",
      "    raise ValueError(f\"Could not find callback with key={token} in the \"\n",
      "\n",
      "ValueError: Could not find callback with key=pyfunc_13 in the registry.\n",
      "\n",
      "\n",
      "\t [[{{node model/landmarks_detector_v3/map/while/PyFunc}}]] [Op:__inference_infer_788]\n",
      "Inference error: Graph execution error:\n",
      "\n",
      "Detected at node 'model/landmarks_detector_v3/map/while/PyFunc' defined at (most recent call last):\n",
      "Node: 'model/landmarks_detector_v3/map/while/PyFunc'\n",
      "ValueError: Could not find callback with key=pyfunc_13 in the registry.\n",
      "Traceback (most recent call last):\n",
      "\n",
      "  File \"D:\\Apps\\anaconda\\envs\\swara\\lib\\site-packages\\tensorflow\\python\\ops\\script_ops.py\", line 256, in __call__\n",
      "    raise ValueError(f\"Could not find callback with key={token} in the \"\n",
      "\n",
      "ValueError: Could not find callback with key=pyfunc_13 in the registry.\n",
      "\n",
      "\n",
      "\t [[{{node model/landmarks_detector_v3/map/while/PyFunc}}]] [Op:__inference_infer_788]\n",
      "Inference error: Graph execution error:\n",
      "\n",
      "Detected at node 'model/landmarks_detector_v3/map/while/PyFunc' defined at (most recent call last):\n",
      "Node: 'model/landmarks_detector_v3/map/while/PyFunc'\n",
      "ValueError: Could not find callback with key=pyfunc_13 in the registry.\n",
      "Traceback (most recent call last):\n",
      "\n",
      "  File \"D:\\Apps\\anaconda\\envs\\swara\\lib\\site-packages\\tensorflow\\python\\ops\\script_ops.py\", line 256, in __call__\n",
      "    raise ValueError(f\"Could not find callback with key={token} in the \"\n",
      "\n",
      "ValueError: Could not find callback with key=pyfunc_13 in the registry.\n",
      "\n",
      "\n",
      "\t [[{{node model/landmarks_detector_v3/map/while/PyFunc}}]] [Op:__inference_infer_788]\n",
      "Inference error: Graph execution error:\n",
      "\n",
      "Detected at node 'model/landmarks_detector_v3/map/while/PyFunc' defined at (most recent call last):\n",
      "Node: 'model/landmarks_detector_v3/map/while/PyFunc'\n",
      "ValueError: Could not find callback with key=pyfunc_13 in the registry.\n",
      "Traceback (most recent call last):\n",
      "\n",
      "  File \"D:\\Apps\\anaconda\\envs\\swara\\lib\\site-packages\\tensorflow\\python\\ops\\script_ops.py\", line 256, in __call__\n",
      "    raise ValueError(f\"Could not find callback with key={token} in the \"\n",
      "\n",
      "ValueError: Could not find callback with key=pyfunc_13 in the registry.\n",
      "\n",
      "\n",
      "\t [[{{node model/landmarks_detector_v3/map/while/PyFunc}}]] [Op:__inference_infer_788]\n",
      "Inference error: Graph execution error:\n",
      "\n",
      "Detected at node 'model/landmarks_detector_v3/map/while/PyFunc' defined at (most recent call last):\n",
      "Node: 'model/landmarks_detector_v3/map/while/PyFunc'\n",
      "ValueError: Could not find callback with key=pyfunc_13 in the registry.\n",
      "Traceback (most recent call last):\n",
      "\n",
      "  File \"D:\\Apps\\anaconda\\envs\\swara\\lib\\site-packages\\tensorflow\\python\\ops\\script_ops.py\", line 256, in __call__\n",
      "    raise ValueError(f\"Could not find callback with key={token} in the \"\n",
      "\n",
      "ValueError: Could not find callback with key=pyfunc_13 in the registry.\n",
      "\n",
      "\n",
      "\t [[{{node model/landmarks_detector_v3/map/while/PyFunc}}]] [Op:__inference_infer_788]\n",
      "Inference error: Graph execution error:\n",
      "\n",
      "Detected at node 'model/landmarks_detector_v3/map/while/PyFunc' defined at (most recent call last):\n",
      "Node: 'model/landmarks_detector_v3/map/while/PyFunc'\n",
      "ValueError: Could not find callback with key=pyfunc_13 in the registry.\n",
      "Traceback (most recent call last):\n",
      "\n",
      "  File \"D:\\Apps\\anaconda\\envs\\swara\\lib\\site-packages\\tensorflow\\python\\ops\\script_ops.py\", line 256, in __call__\n",
      "    raise ValueError(f\"Could not find callback with key={token} in the \"\n",
      "\n",
      "ValueError: Could not find callback with key=pyfunc_13 in the registry.\n",
      "\n",
      "\n",
      "\t [[{{node model/landmarks_detector_v3/map/while/PyFunc}}]] [Op:__inference_infer_788]\n",
      "Inference error: Graph execution error:\n",
      "\n",
      "Detected at node 'model/landmarks_detector_v3/map/while/PyFunc' defined at (most recent call last):\n",
      "Node: 'model/landmarks_detector_v3/map/while/PyFunc'\n",
      "ValueError: Could not find callback with key=pyfunc_13 in the registry.\n",
      "Traceback (most recent call last):\n",
      "\n",
      "  File \"D:\\Apps\\anaconda\\envs\\swara\\lib\\site-packages\\tensorflow\\python\\ops\\script_ops.py\", line 256, in __call__\n",
      "    raise ValueError(f\"Could not find callback with key={token} in the \"\n",
      "\n",
      "ValueError: Could not find callback with key=pyfunc_13 in the registry.\n",
      "\n",
      "\n",
      "\t [[{{node model/landmarks_detector_v3/map/while/PyFunc}}]] [Op:__inference_infer_788]\n",
      "Inference error: Graph execution error:\n",
      "\n",
      "Detected at node 'model/landmarks_detector_v3/map/while/PyFunc' defined at (most recent call last):\n",
      "Node: 'model/landmarks_detector_v3/map/while/PyFunc'\n",
      "ValueError: Could not find callback with key=pyfunc_13 in the registry.\n",
      "Traceback (most recent call last):\n",
      "\n",
      "  File \"D:\\Apps\\anaconda\\envs\\swara\\lib\\site-packages\\tensorflow\\python\\ops\\script_ops.py\", line 256, in __call__\n",
      "    raise ValueError(f\"Could not find callback with key={token} in the \"\n",
      "\n",
      "ValueError: Could not find callback with key=pyfunc_13 in the registry.\n",
      "\n",
      "\n",
      "\t [[{{node model/landmarks_detector_v3/map/while/PyFunc}}]] [Op:__inference_infer_788]\n",
      "Inference error: Graph execution error:\n",
      "\n",
      "Detected at node 'model/landmarks_detector_v3/map/while/PyFunc' defined at (most recent call last):\n",
      "Node: 'model/landmarks_detector_v3/map/while/PyFunc'\n",
      "ValueError: Could not find callback with key=pyfunc_13 in the registry.\n",
      "Traceback (most recent call last):\n",
      "\n",
      "  File \"D:\\Apps\\anaconda\\envs\\swara\\lib\\site-packages\\tensorflow\\python\\ops\\script_ops.py\", line 256, in __call__\n",
      "    raise ValueError(f\"Could not find callback with key={token} in the \"\n",
      "\n",
      "ValueError: Could not find callback with key=pyfunc_13 in the registry.\n",
      "\n",
      "\n",
      "\t [[{{node model/landmarks_detector_v3/map/while/PyFunc}}]] [Op:__inference_infer_788]\n",
      "Inference error: Graph execution error:\n",
      "\n",
      "Detected at node 'model/landmarks_detector_v3/map/while/PyFunc' defined at (most recent call last):\n",
      "Node: 'model/landmarks_detector_v3/map/while/PyFunc'\n",
      "ValueError: Could not find callback with key=pyfunc_13 in the registry.\n",
      "Traceback (most recent call last):\n",
      "\n",
      "  File \"D:\\Apps\\anaconda\\envs\\swara\\lib\\site-packages\\tensorflow\\python\\ops\\script_ops.py\", line 256, in __call__\n",
      "    raise ValueError(f\"Could not find callback with key={token} in the \"\n",
      "\n",
      "ValueError: Could not find callback with key=pyfunc_13 in the registry.\n",
      "\n",
      "\n",
      "\t [[{{node model/landmarks_detector_v3/map/while/PyFunc}}]] [Op:__inference_infer_788]\n",
      "Inference error: Graph execution error:\n",
      "\n",
      "Detected at node 'model/landmarks_detector_v3/map/while/PyFunc' defined at (most recent call last):\n",
      "Node: 'model/landmarks_detector_v3/map/while/PyFunc'\n",
      "ValueError: Could not find callback with key=pyfunc_13 in the registry.\n",
      "Traceback (most recent call last):\n",
      "\n",
      "  File \"D:\\Apps\\anaconda\\envs\\swara\\lib\\site-packages\\tensorflow\\python\\ops\\script_ops.py\", line 256, in __call__\n",
      "    raise ValueError(f\"Could not find callback with key={token} in the \"\n",
      "\n",
      "ValueError: Could not find callback with key=pyfunc_13 in the registry.\n",
      "\n",
      "\n",
      "\t [[{{node model/landmarks_detector_v3/map/while/PyFunc}}]] [Op:__inference_infer_788]\n",
      "Inference error: Graph execution error:\n",
      "\n",
      "Detected at node 'model/landmarks_detector_v3/map/while/PyFunc' defined at (most recent call last):\n",
      "Node: 'model/landmarks_detector_v3/map/while/PyFunc'\n",
      "ValueError: Could not find callback with key=pyfunc_13 in the registry.\n",
      "Traceback (most recent call last):\n",
      "\n",
      "  File \"D:\\Apps\\anaconda\\envs\\swara\\lib\\site-packages\\tensorflow\\python\\ops\\script_ops.py\", line 256, in __call__\n",
      "    raise ValueError(f\"Could not find callback with key={token} in the \"\n",
      "\n",
      "ValueError: Could not find callback with key=pyfunc_13 in the registry.\n",
      "\n",
      "\n",
      "\t [[{{node model/landmarks_detector_v3/map/while/PyFunc}}]] [Op:__inference_infer_788]\n",
      "Inference error: Graph execution error:\n",
      "\n",
      "Detected at node 'model/landmarks_detector_v3/map/while/PyFunc' defined at (most recent call last):\n",
      "Node: 'model/landmarks_detector_v3/map/while/PyFunc'\n",
      "ValueError: Could not find callback with key=pyfunc_13 in the registry.\n",
      "Traceback (most recent call last):\n",
      "\n",
      "  File \"D:\\Apps\\anaconda\\envs\\swara\\lib\\site-packages\\tensorflow\\python\\ops\\script_ops.py\", line 256, in __call__\n",
      "    raise ValueError(f\"Could not find callback with key={token} in the \"\n",
      "\n",
      "ValueError: Could not find callback with key=pyfunc_13 in the registry.\n",
      "\n",
      "\n",
      "\t [[{{node model/landmarks_detector_v3/map/while/PyFunc}}]] [Op:__inference_infer_788]\n",
      "Inference error: Graph execution error:\n",
      "\n",
      "Detected at node 'model/landmarks_detector_v3/map/while/PyFunc' defined at (most recent call last):\n",
      "Node: 'model/landmarks_detector_v3/map/while/PyFunc'\n",
      "ValueError: Could not find callback with key=pyfunc_13 in the registry.\n",
      "Traceback (most recent call last):\n",
      "\n",
      "  File \"D:\\Apps\\anaconda\\envs\\swara\\lib\\site-packages\\tensorflow\\python\\ops\\script_ops.py\", line 256, in __call__\n",
      "    raise ValueError(f\"Could not find callback with key={token} in the \"\n",
      "\n",
      "ValueError: Could not find callback with key=pyfunc_13 in the registry.\n",
      "\n",
      "\n",
      "\t [[{{node model/landmarks_detector_v3/map/while/PyFunc}}]] [Op:__inference_infer_788]\n",
      "Inference error: Graph execution error:\n",
      "\n",
      "Detected at node 'model/landmarks_detector_v3/map/while/PyFunc' defined at (most recent call last):\n",
      "Node: 'model/landmarks_detector_v3/map/while/PyFunc'\n",
      "ValueError: Could not find callback with key=pyfunc_13 in the registry.\n",
      "Traceback (most recent call last):\n",
      "\n",
      "  File \"D:\\Apps\\anaconda\\envs\\swara\\lib\\site-packages\\tensorflow\\python\\ops\\script_ops.py\", line 256, in __call__\n",
      "    raise ValueError(f\"Could not find callback with key={token} in the \"\n",
      "\n",
      "ValueError: Could not find callback with key=pyfunc_13 in the registry.\n",
      "\n",
      "\n",
      "\t [[{{node model/landmarks_detector_v3/map/while/PyFunc}}]] [Op:__inference_infer_788]\n",
      "Inference error: Graph execution error:\n",
      "\n",
      "Detected at node 'model/landmarks_detector_v3/map/while/PyFunc' defined at (most recent call last):\n",
      "Node: 'model/landmarks_detector_v3/map/while/PyFunc'\n",
      "ValueError: Could not find callback with key=pyfunc_13 in the registry.\n",
      "Traceback (most recent call last):\n",
      "\n",
      "  File \"D:\\Apps\\anaconda\\envs\\swara\\lib\\site-packages\\tensorflow\\python\\ops\\script_ops.py\", line 256, in __call__\n",
      "    raise ValueError(f\"Could not find callback with key={token} in the \"\n",
      "\n",
      "ValueError: Could not find callback with key=pyfunc_13 in the registry.\n",
      "\n",
      "\n",
      "\t [[{{node model/landmarks_detector_v3/map/while/PyFunc}}]] [Op:__inference_infer_788]\n",
      "Inference error: Graph execution error:\n",
      "\n",
      "Detected at node 'model/landmarks_detector_v3/map/while/PyFunc' defined at (most recent call last):\n",
      "Node: 'model/landmarks_detector_v3/map/while/PyFunc'\n",
      "ValueError: Could not find callback with key=pyfunc_13 in the registry.\n",
      "Traceback (most recent call last):\n",
      "\n",
      "  File \"D:\\Apps\\anaconda\\envs\\swara\\lib\\site-packages\\tensorflow\\python\\ops\\script_ops.py\", line 256, in __call__\n",
      "    raise ValueError(f\"Could not find callback with key={token} in the \"\n",
      "\n",
      "ValueError: Could not find callback with key=pyfunc_13 in the registry.\n",
      "\n",
      "\n",
      "\t [[{{node model/landmarks_detector_v3/map/while/PyFunc}}]] [Op:__inference_infer_788]\n",
      "Inference error: Graph execution error:\n",
      "\n",
      "Detected at node 'model/landmarks_detector_v3/map/while/PyFunc' defined at (most recent call last):\n",
      "Node: 'model/landmarks_detector_v3/map/while/PyFunc'\n",
      "ValueError: Could not find callback with key=pyfunc_13 in the registry.\n",
      "Traceback (most recent call last):\n",
      "\n",
      "  File \"D:\\Apps\\anaconda\\envs\\swara\\lib\\site-packages\\tensorflow\\python\\ops\\script_ops.py\", line 256, in __call__\n",
      "    raise ValueError(f\"Could not find callback with key={token} in the \"\n",
      "\n",
      "ValueError: Could not find callback with key=pyfunc_13 in the registry.\n",
      "\n",
      "\n",
      "\t [[{{node model/landmarks_detector_v3/map/while/PyFunc}}]] [Op:__inference_infer_788]\n",
      "Inference error: Graph execution error:\n",
      "\n",
      "Detected at node 'model/landmarks_detector_v3/map/while/PyFunc' defined at (most recent call last):\n",
      "Node: 'model/landmarks_detector_v3/map/while/PyFunc'\n",
      "ValueError: Could not find callback with key=pyfunc_13 in the registry.\n",
      "Traceback (most recent call last):\n",
      "\n",
      "  File \"D:\\Apps\\anaconda\\envs\\swara\\lib\\site-packages\\tensorflow\\python\\ops\\script_ops.py\", line 256, in __call__\n",
      "    raise ValueError(f\"Could not find callback with key={token} in the \"\n",
      "\n",
      "ValueError: Could not find callback with key=pyfunc_13 in the registry.\n",
      "\n",
      "\n",
      "\t [[{{node model/landmarks_detector_v3/map/while/PyFunc}}]] [Op:__inference_infer_788]\n",
      "Inference error: Graph execution error:\n",
      "\n",
      "Detected at node 'model/landmarks_detector_v3/map/while/PyFunc' defined at (most recent call last):\n",
      "Node: 'model/landmarks_detector_v3/map/while/PyFunc'\n",
      "ValueError: Could not find callback with key=pyfunc_13 in the registry.\n",
      "Traceback (most recent call last):\n",
      "\n",
      "  File \"D:\\Apps\\anaconda\\envs\\swara\\lib\\site-packages\\tensorflow\\python\\ops\\script_ops.py\", line 256, in __call__\n",
      "    raise ValueError(f\"Could not find callback with key={token} in the \"\n",
      "\n",
      "ValueError: Could not find callback with key=pyfunc_13 in the registry.\n",
      "\n",
      "\n",
      "\t [[{{node model/landmarks_detector_v3/map/while/PyFunc}}]] [Op:__inference_infer_788]\n",
      "Inference error: Graph execution error:\n",
      "\n",
      "Detected at node 'model/landmarks_detector_v3/map/while/PyFunc' defined at (most recent call last):\n",
      "Node: 'model/landmarks_detector_v3/map/while/PyFunc'\n",
      "ValueError: Could not find callback with key=pyfunc_13 in the registry.\n",
      "Traceback (most recent call last):\n",
      "\n",
      "  File \"D:\\Apps\\anaconda\\envs\\swara\\lib\\site-packages\\tensorflow\\python\\ops\\script_ops.py\", line 256, in __call__\n",
      "    raise ValueError(f\"Could not find callback with key={token} in the \"\n",
      "\n",
      "ValueError: Could not find callback with key=pyfunc_13 in the registry.\n",
      "\n",
      "\n",
      "\t [[{{node model/landmarks_detector_v3/map/while/PyFunc}}]] [Op:__inference_infer_788]\n",
      "Inference error: Graph execution error:\n",
      "\n",
      "Detected at node 'model/landmarks_detector_v3/map/while/PyFunc' defined at (most recent call last):\n",
      "Node: 'model/landmarks_detector_v3/map/while/PyFunc'\n",
      "ValueError: Could not find callback with key=pyfunc_13 in the registry.\n",
      "Traceback (most recent call last):\n",
      "\n",
      "  File \"D:\\Apps\\anaconda\\envs\\swara\\lib\\site-packages\\tensorflow\\python\\ops\\script_ops.py\", line 256, in __call__\n",
      "    raise ValueError(f\"Could not find callback with key={token} in the \"\n",
      "\n",
      "ValueError: Could not find callback with key=pyfunc_13 in the registry.\n",
      "\n",
      "\n",
      "\t [[{{node model/landmarks_detector_v3/map/while/PyFunc}}]] [Op:__inference_infer_788]\n",
      "Inference error: Graph execution error:\n",
      "\n",
      "Detected at node 'model/landmarks_detector_v3/map/while/PyFunc' defined at (most recent call last):\n",
      "Node: 'model/landmarks_detector_v3/map/while/PyFunc'\n",
      "ValueError: Could not find callback with key=pyfunc_13 in the registry.\n",
      "Traceback (most recent call last):\n",
      "\n",
      "  File \"D:\\Apps\\anaconda\\envs\\swara\\lib\\site-packages\\tensorflow\\python\\ops\\script_ops.py\", line 256, in __call__\n",
      "    raise ValueError(f\"Could not find callback with key={token} in the \"\n",
      "\n",
      "ValueError: Could not find callback with key=pyfunc_13 in the registry.\n",
      "\n",
      "\n",
      "\t [[{{node model/landmarks_detector_v3/map/while/PyFunc}}]] [Op:__inference_infer_788]\n",
      "Inference error: Graph execution error:\n",
      "\n",
      "Detected at node 'model/landmarks_detector_v3/map/while/PyFunc' defined at (most recent call last):\n",
      "Node: 'model/landmarks_detector_v3/map/while/PyFunc'\n",
      "ValueError: Could not find callback with key=pyfunc_13 in the registry.\n",
      "Traceback (most recent call last):\n",
      "\n",
      "  File \"D:\\Apps\\anaconda\\envs\\swara\\lib\\site-packages\\tensorflow\\python\\ops\\script_ops.py\", line 256, in __call__\n",
      "    raise ValueError(f\"Could not find callback with key={token} in the \"\n",
      "\n",
      "ValueError: Could not find callback with key=pyfunc_13 in the registry.\n",
      "\n",
      "\n",
      "\t [[{{node model/landmarks_detector_v3/map/while/PyFunc}}]] [Op:__inference_infer_788]\n",
      "Inference error: Graph execution error:\n",
      "\n",
      "Detected at node 'model/landmarks_detector_v3/map/while/PyFunc' defined at (most recent call last):\n",
      "Node: 'model/landmarks_detector_v3/map/while/PyFunc'\n",
      "ValueError: Could not find callback with key=pyfunc_13 in the registry.\n",
      "Traceback (most recent call last):\n",
      "\n",
      "  File \"D:\\Apps\\anaconda\\envs\\swara\\lib\\site-packages\\tensorflow\\python\\ops\\script_ops.py\", line 256, in __call__\n",
      "    raise ValueError(f\"Could not find callback with key={token} in the \"\n",
      "\n",
      "ValueError: Could not find callback with key=pyfunc_13 in the registry.\n",
      "\n",
      "\n",
      "\t [[{{node model/landmarks_detector_v3/map/while/PyFunc}}]] [Op:__inference_infer_788]\n",
      "Inference error: Graph execution error:\n",
      "\n",
      "Detected at node 'model/landmarks_detector_v3/map/while/PyFunc' defined at (most recent call last):\n",
      "Node: 'model/landmarks_detector_v3/map/while/PyFunc'\n",
      "ValueError: Could not find callback with key=pyfunc_13 in the registry.\n",
      "Traceback (most recent call last):\n",
      "\n",
      "  File \"D:\\Apps\\anaconda\\envs\\swara\\lib\\site-packages\\tensorflow\\python\\ops\\script_ops.py\", line 256, in __call__\n",
      "    raise ValueError(f\"Could not find callback with key={token} in the \"\n",
      "\n",
      "ValueError: Could not find callback with key=pyfunc_13 in the registry.\n",
      "\n",
      "\n",
      "\t [[{{node model/landmarks_detector_v3/map/while/PyFunc}}]] [Op:__inference_infer_788]\n",
      "Inference error: Graph execution error:\n",
      "\n",
      "Detected at node 'model/landmarks_detector_v3/map/while/PyFunc' defined at (most recent call last):\n",
      "Node: 'model/landmarks_detector_v3/map/while/PyFunc'\n",
      "ValueError: Could not find callback with key=pyfunc_13 in the registry.\n",
      "Traceback (most recent call last):\n",
      "\n",
      "  File \"D:\\Apps\\anaconda\\envs\\swara\\lib\\site-packages\\tensorflow\\python\\ops\\script_ops.py\", line 256, in __call__\n",
      "    raise ValueError(f\"Could not find callback with key={token} in the \"\n",
      "\n",
      "ValueError: Could not find callback with key=pyfunc_13 in the registry.\n",
      "\n",
      "\n",
      "\t [[{{node model/landmarks_detector_v3/map/while/PyFunc}}]] [Op:__inference_infer_788]\n",
      "Inference error: Graph execution error:\n",
      "\n",
      "Detected at node 'model/landmarks_detector_v3/map/while/PyFunc' defined at (most recent call last):\n",
      "Node: 'model/landmarks_detector_v3/map/while/PyFunc'\n",
      "ValueError: Could not find callback with key=pyfunc_13 in the registry.\n",
      "Traceback (most recent call last):\n",
      "\n",
      "  File \"D:\\Apps\\anaconda\\envs\\swara\\lib\\site-packages\\tensorflow\\python\\ops\\script_ops.py\", line 256, in __call__\n",
      "    raise ValueError(f\"Could not find callback with key={token} in the \"\n",
      "\n",
      "ValueError: Could not find callback with key=pyfunc_13 in the registry.\n",
      "\n",
      "\n",
      "\t [[{{node model/landmarks_detector_v3/map/while/PyFunc}}]] [Op:__inference_infer_788]\n",
      "Inference error: Graph execution error:\n",
      "\n",
      "Detected at node 'model/landmarks_detector_v3/map/while/PyFunc' defined at (most recent call last):\n",
      "Node: 'model/landmarks_detector_v3/map/while/PyFunc'\n",
      "ValueError: Could not find callback with key=pyfunc_13 in the registry.\n",
      "Traceback (most recent call last):\n",
      "\n",
      "  File \"D:\\Apps\\anaconda\\envs\\swara\\lib\\site-packages\\tensorflow\\python\\ops\\script_ops.py\", line 256, in __call__\n",
      "    raise ValueError(f\"Could not find callback with key={token} in the \"\n",
      "\n",
      "ValueError: Could not find callback with key=pyfunc_13 in the registry.\n",
      "\n",
      "\n",
      "\t [[{{node model/landmarks_detector_v3/map/while/PyFunc}}]] [Op:__inference_infer_788]\n",
      "Inference error: Graph execution error:\n",
      "\n",
      "Detected at node 'model/landmarks_detector_v3/map/while/PyFunc' defined at (most recent call last):\n",
      "Node: 'model/landmarks_detector_v3/map/while/PyFunc'\n",
      "ValueError: Could not find callback with key=pyfunc_13 in the registry.\n",
      "Traceback (most recent call last):\n",
      "\n",
      "  File \"D:\\Apps\\anaconda\\envs\\swara\\lib\\site-packages\\tensorflow\\python\\ops\\script_ops.py\", line 256, in __call__\n",
      "    raise ValueError(f\"Could not find callback with key={token} in the \"\n",
      "\n",
      "ValueError: Could not find callback with key=pyfunc_13 in the registry.\n",
      "\n",
      "\n",
      "\t [[{{node model/landmarks_detector_v3/map/while/PyFunc}}]] [Op:__inference_infer_788]\n",
      "Inference error: Graph execution error:\n",
      "\n",
      "Detected at node 'model/landmarks_detector_v3/map/while/PyFunc' defined at (most recent call last):\n",
      "Node: 'model/landmarks_detector_v3/map/while/PyFunc'\n",
      "ValueError: Could not find callback with key=pyfunc_13 in the registry.\n",
      "Traceback (most recent call last):\n",
      "\n",
      "  File \"D:\\Apps\\anaconda\\envs\\swara\\lib\\site-packages\\tensorflow\\python\\ops\\script_ops.py\", line 256, in __call__\n",
      "    raise ValueError(f\"Could not find callback with key={token} in the \"\n",
      "\n",
      "ValueError: Could not find callback with key=pyfunc_13 in the registry.\n",
      "\n",
      "\n",
      "\t [[{{node model/landmarks_detector_v3/map/while/PyFunc}}]] [Op:__inference_infer_788]\n",
      "Inference error: Graph execution error:\n",
      "\n",
      "Detected at node 'model/landmarks_detector_v3/map/while/PyFunc' defined at (most recent call last):\n",
      "Node: 'model/landmarks_detector_v3/map/while/PyFunc'\n",
      "ValueError: Could not find callback with key=pyfunc_13 in the registry.\n",
      "Traceback (most recent call last):\n",
      "\n",
      "  File \"D:\\Apps\\anaconda\\envs\\swara\\lib\\site-packages\\tensorflow\\python\\ops\\script_ops.py\", line 256, in __call__\n",
      "    raise ValueError(f\"Could not find callback with key={token} in the \"\n",
      "\n",
      "ValueError: Could not find callback with key=pyfunc_13 in the registry.\n",
      "\n",
      "\n",
      "\t [[{{node model/landmarks_detector_v3/map/while/PyFunc}}]] [Op:__inference_infer_788]\n",
      "Inference error: Graph execution error:\n",
      "\n",
      "Detected at node 'model/landmarks_detector_v3/map/while/PyFunc' defined at (most recent call last):\n",
      "Node: 'model/landmarks_detector_v3/map/while/PyFunc'\n",
      "ValueError: Could not find callback with key=pyfunc_13 in the registry.\n",
      "Traceback (most recent call last):\n",
      "\n",
      "  File \"D:\\Apps\\anaconda\\envs\\swara\\lib\\site-packages\\tensorflow\\python\\ops\\script_ops.py\", line 256, in __call__\n",
      "    raise ValueError(f\"Could not find callback with key={token} in the \"\n",
      "\n",
      "ValueError: Could not find callback with key=pyfunc_13 in the registry.\n",
      "\n",
      "\n",
      "\t [[{{node model/landmarks_detector_v3/map/while/PyFunc}}]] [Op:__inference_infer_788]\n",
      "Inference error: Graph execution error:\n",
      "\n",
      "Detected at node 'model/landmarks_detector_v3/map/while/PyFunc' defined at (most recent call last):\n",
      "Node: 'model/landmarks_detector_v3/map/while/PyFunc'\n",
      "ValueError: Could not find callback with key=pyfunc_13 in the registry.\n",
      "Traceback (most recent call last):\n",
      "\n",
      "  File \"D:\\Apps\\anaconda\\envs\\swara\\lib\\site-packages\\tensorflow\\python\\ops\\script_ops.py\", line 256, in __call__\n",
      "    raise ValueError(f\"Could not find callback with key={token} in the \"\n",
      "\n",
      "ValueError: Could not find callback with key=pyfunc_13 in the registry.\n",
      "\n",
      "\n",
      "\t [[{{node model/landmarks_detector_v3/map/while/PyFunc}}]] [Op:__inference_infer_788]\n",
      "Inference error: Graph execution error:\n",
      "\n",
      "Detected at node 'model/landmarks_detector_v3/map/while/PyFunc' defined at (most recent call last):\n",
      "Node: 'model/landmarks_detector_v3/map/while/PyFunc'\n",
      "ValueError: Could not find callback with key=pyfunc_13 in the registry.\n",
      "Traceback (most recent call last):\n",
      "\n",
      "  File \"D:\\Apps\\anaconda\\envs\\swara\\lib\\site-packages\\tensorflow\\python\\ops\\script_ops.py\", line 256, in __call__\n",
      "    raise ValueError(f\"Could not find callback with key={token} in the \"\n",
      "\n",
      "ValueError: Could not find callback with key=pyfunc_13 in the registry.\n",
      "\n",
      "\n",
      "\t [[{{node model/landmarks_detector_v3/map/while/PyFunc}}]] [Op:__inference_infer_788]\n",
      "Inference error: Graph execution error:\n",
      "\n",
      "Detected at node 'model/landmarks_detector_v3/map/while/PyFunc' defined at (most recent call last):\n",
      "Node: 'model/landmarks_detector_v3/map/while/PyFunc'\n",
      "ValueError: Could not find callback with key=pyfunc_13 in the registry.\n",
      "Traceback (most recent call last):\n",
      "\n",
      "  File \"D:\\Apps\\anaconda\\envs\\swara\\lib\\site-packages\\tensorflow\\python\\ops\\script_ops.py\", line 256, in __call__\n",
      "    raise ValueError(f\"Could not find callback with key={token} in the \"\n",
      "\n",
      "ValueError: Could not find callback with key=pyfunc_13 in the registry.\n",
      "\n",
      "\n",
      "\t [[{{node model/landmarks_detector_v3/map/while/PyFunc}}]] [Op:__inference_infer_788]\n",
      "Inference error: Graph execution error:\n",
      "\n",
      "Detected at node 'model/landmarks_detector_v3/map/while/PyFunc' defined at (most recent call last):\n",
      "Node: 'model/landmarks_detector_v3/map/while/PyFunc'\n",
      "ValueError: Could not find callback with key=pyfunc_13 in the registry.\n",
      "Traceback (most recent call last):\n",
      "\n",
      "  File \"D:\\Apps\\anaconda\\envs\\swara\\lib\\site-packages\\tensorflow\\python\\ops\\script_ops.py\", line 256, in __call__\n",
      "    raise ValueError(f\"Could not find callback with key={token} in the \"\n",
      "\n",
      "ValueError: Could not find callback with key=pyfunc_13 in the registry.\n",
      "\n",
      "\n",
      "\t [[{{node model/landmarks_detector_v3/map/while/PyFunc}}]] [Op:__inference_infer_788]\n",
      "Inference error: Graph execution error:\n",
      "\n",
      "Detected at node 'model/landmarks_detector_v3/map/while/PyFunc' defined at (most recent call last):\n",
      "Node: 'model/landmarks_detector_v3/map/while/PyFunc'\n",
      "ValueError: Could not find callback with key=pyfunc_13 in the registry.\n",
      "Traceback (most recent call last):\n",
      "\n",
      "  File \"D:\\Apps\\anaconda\\envs\\swara\\lib\\site-packages\\tensorflow\\python\\ops\\script_ops.py\", line 256, in __call__\n",
      "    raise ValueError(f\"Could not find callback with key={token} in the \"\n",
      "\n",
      "ValueError: Could not find callback with key=pyfunc_13 in the registry.\n",
      "\n",
      "\n",
      "\t [[{{node model/landmarks_detector_v3/map/while/PyFunc}}]] [Op:__inference_infer_788]\n",
      "Inference error: Graph execution error:\n",
      "\n",
      "Detected at node 'model/landmarks_detector_v3/map/while/PyFunc' defined at (most recent call last):\n",
      "Node: 'model/landmarks_detector_v3/map/while/PyFunc'\n",
      "ValueError: Could not find callback with key=pyfunc_13 in the registry.\n",
      "Traceback (most recent call last):\n",
      "\n",
      "  File \"D:\\Apps\\anaconda\\envs\\swara\\lib\\site-packages\\tensorflow\\python\\ops\\script_ops.py\", line 256, in __call__\n",
      "    raise ValueError(f\"Could not find callback with key={token} in the \"\n",
      "\n",
      "ValueError: Could not find callback with key=pyfunc_13 in the registry.\n",
      "\n",
      "\n",
      "\t [[{{node model/landmarks_detector_v3/map/while/PyFunc}}]] [Op:__inference_infer_788]\n",
      "Inference error: Graph execution error:\n",
      "\n",
      "Detected at node 'model/landmarks_detector_v3/map/while/PyFunc' defined at (most recent call last):\n",
      "Node: 'model/landmarks_detector_v3/map/while/PyFunc'\n",
      "ValueError: Could not find callback with key=pyfunc_13 in the registry.\n",
      "Traceback (most recent call last):\n",
      "\n",
      "  File \"D:\\Apps\\anaconda\\envs\\swara\\lib\\site-packages\\tensorflow\\python\\ops\\script_ops.py\", line 256, in __call__\n",
      "    raise ValueError(f\"Could not find callback with key={token} in the \"\n",
      "\n",
      "ValueError: Could not find callback with key=pyfunc_13 in the registry.\n",
      "\n",
      "\n",
      "\t [[{{node model/landmarks_detector_v3/map/while/PyFunc}}]] [Op:__inference_infer_788]\n",
      "Inference error: Graph execution error:\n",
      "\n",
      "Detected at node 'model/landmarks_detector_v3/map/while/PyFunc' defined at (most recent call last):\n",
      "Node: 'model/landmarks_detector_v3/map/while/PyFunc'\n",
      "ValueError: Could not find callback with key=pyfunc_13 in the registry.\n",
      "Traceback (most recent call last):\n",
      "\n",
      "  File \"D:\\Apps\\anaconda\\envs\\swara\\lib\\site-packages\\tensorflow\\python\\ops\\script_ops.py\", line 256, in __call__\n",
      "    raise ValueError(f\"Could not find callback with key={token} in the \"\n",
      "\n",
      "ValueError: Could not find callback with key=pyfunc_13 in the registry.\n",
      "\n",
      "\n",
      "\t [[{{node model/landmarks_detector_v3/map/while/PyFunc}}]] [Op:__inference_infer_788]\n",
      "Inference error: Graph execution error:\n",
      "\n",
      "Detected at node 'model/landmarks_detector_v3/map/while/PyFunc' defined at (most recent call last):\n",
      "Node: 'model/landmarks_detector_v3/map/while/PyFunc'\n",
      "ValueError: Could not find callback with key=pyfunc_13 in the registry.\n",
      "Traceback (most recent call last):\n",
      "\n",
      "  File \"D:\\Apps\\anaconda\\envs\\swara\\lib\\site-packages\\tensorflow\\python\\ops\\script_ops.py\", line 256, in __call__\n",
      "    raise ValueError(f\"Could not find callback with key={token} in the \"\n",
      "\n",
      "ValueError: Could not find callback with key=pyfunc_13 in the registry.\n",
      "\n",
      "\n",
      "\t [[{{node model/landmarks_detector_v3/map/while/PyFunc}}]] [Op:__inference_infer_788]\n",
      "Inference error: Graph execution error:\n",
      "\n",
      "Detected at node 'model/landmarks_detector_v3/map/while/PyFunc' defined at (most recent call last):\n",
      "Node: 'model/landmarks_detector_v3/map/while/PyFunc'\n",
      "ValueError: Could not find callback with key=pyfunc_13 in the registry.\n",
      "Traceback (most recent call last):\n",
      "\n",
      "  File \"D:\\Apps\\anaconda\\envs\\swara\\lib\\site-packages\\tensorflow\\python\\ops\\script_ops.py\", line 256, in __call__\n",
      "    raise ValueError(f\"Could not find callback with key={token} in the \"\n",
      "\n",
      "ValueError: Could not find callback with key=pyfunc_13 in the registry.\n",
      "\n",
      "\n",
      "\t [[{{node model/landmarks_detector_v3/map/while/PyFunc}}]] [Op:__inference_infer_788]\n",
      "Inference error: Graph execution error:\n",
      "\n",
      "Detected at node 'model/landmarks_detector_v3/map/while/PyFunc' defined at (most recent call last):\n",
      "Node: 'model/landmarks_detector_v3/map/while/PyFunc'\n",
      "ValueError: Could not find callback with key=pyfunc_13 in the registry.\n",
      "Traceback (most recent call last):\n",
      "\n",
      "  File \"D:\\Apps\\anaconda\\envs\\swara\\lib\\site-packages\\tensorflow\\python\\ops\\script_ops.py\", line 256, in __call__\n",
      "    raise ValueError(f\"Could not find callback with key={token} in the \"\n",
      "\n",
      "ValueError: Could not find callback with key=pyfunc_13 in the registry.\n",
      "\n",
      "\n",
      "\t [[{{node model/landmarks_detector_v3/map/while/PyFunc}}]] [Op:__inference_infer_788]\n",
      "Inference error: Graph execution error:\n",
      "\n",
      "Detected at node 'model/landmarks_detector_v3/map/while/PyFunc' defined at (most recent call last):\n",
      "Node: 'model/landmarks_detector_v3/map/while/PyFunc'\n",
      "ValueError: Could not find callback with key=pyfunc_13 in the registry.\n",
      "Traceback (most recent call last):\n",
      "\n",
      "  File \"D:\\Apps\\anaconda\\envs\\swara\\lib\\site-packages\\tensorflow\\python\\ops\\script_ops.py\", line 256, in __call__\n",
      "    raise ValueError(f\"Could not find callback with key={token} in the \"\n",
      "\n",
      "ValueError: Could not find callback with key=pyfunc_13 in the registry.\n",
      "\n",
      "\n",
      "\t [[{{node model/landmarks_detector_v3/map/while/PyFunc}}]] [Op:__inference_infer_788]\n",
      "Inference error: Graph execution error:\n",
      "\n",
      "Detected at node 'model/landmarks_detector_v3/map/while/PyFunc' defined at (most recent call last):\n",
      "Node: 'model/landmarks_detector_v3/map/while/PyFunc'\n",
      "ValueError: Could not find callback with key=pyfunc_13 in the registry.\n",
      "Traceback (most recent call last):\n",
      "\n",
      "  File \"D:\\Apps\\anaconda\\envs\\swara\\lib\\site-packages\\tensorflow\\python\\ops\\script_ops.py\", line 256, in __call__\n",
      "    raise ValueError(f\"Could not find callback with key={token} in the \"\n",
      "\n",
      "ValueError: Could not find callback with key=pyfunc_13 in the registry.\n",
      "\n",
      "\n",
      "\t [[{{node model/landmarks_detector_v3/map/while/PyFunc}}]] [Op:__inference_infer_788]\n",
      "Inference error: Graph execution error:\n",
      "\n",
      "Detected at node 'model/landmarks_detector_v3/map/while/PyFunc' defined at (most recent call last):\n",
      "Node: 'model/landmarks_detector_v3/map/while/PyFunc'\n",
      "ValueError: Could not find callback with key=pyfunc_13 in the registry.\n",
      "Traceback (most recent call last):\n",
      "\n",
      "  File \"D:\\Apps\\anaconda\\envs\\swara\\lib\\site-packages\\tensorflow\\python\\ops\\script_ops.py\", line 256, in __call__\n",
      "    raise ValueError(f\"Could not find callback with key={token} in the \"\n",
      "\n",
      "ValueError: Could not find callback with key=pyfunc_13 in the registry.\n",
      "\n",
      "\n",
      "\t [[{{node model/landmarks_detector_v3/map/while/PyFunc}}]] [Op:__inference_infer_788]\n",
      "Inference error: Graph execution error:\n",
      "\n",
      "Detected at node 'model/landmarks_detector_v3/map/while/PyFunc' defined at (most recent call last):\n",
      "Node: 'model/landmarks_detector_v3/map/while/PyFunc'\n",
      "ValueError: Could not find callback with key=pyfunc_13 in the registry.\n",
      "Traceback (most recent call last):\n",
      "\n",
      "  File \"D:\\Apps\\anaconda\\envs\\swara\\lib\\site-packages\\tensorflow\\python\\ops\\script_ops.py\", line 256, in __call__\n",
      "    raise ValueError(f\"Could not find callback with key={token} in the \"\n",
      "\n",
      "ValueError: Could not find callback with key=pyfunc_13 in the registry.\n",
      "\n",
      "\n",
      "\t [[{{node model/landmarks_detector_v3/map/while/PyFunc}}]] [Op:__inference_infer_788]\n",
      "Inference error: Graph execution error:\n",
      "\n",
      "Detected at node 'model/landmarks_detector_v3/map/while/PyFunc' defined at (most recent call last):\n",
      "Node: 'model/landmarks_detector_v3/map/while/PyFunc'\n",
      "ValueError: Could not find callback with key=pyfunc_13 in the registry.\n",
      "Traceback (most recent call last):\n",
      "\n",
      "  File \"D:\\Apps\\anaconda\\envs\\swara\\lib\\site-packages\\tensorflow\\python\\ops\\script_ops.py\", line 256, in __call__\n",
      "    raise ValueError(f\"Could not find callback with key={token} in the \"\n",
      "\n",
      "ValueError: Could not find callback with key=pyfunc_13 in the registry.\n",
      "\n",
      "\n",
      "\t [[{{node model/landmarks_detector_v3/map/while/PyFunc}}]] [Op:__inference_infer_788]\n",
      "Inference error: Graph execution error:\n",
      "\n",
      "Detected at node 'model/landmarks_detector_v3/map/while/PyFunc' defined at (most recent call last):\n",
      "Node: 'model/landmarks_detector_v3/map/while/PyFunc'\n",
      "ValueError: Could not find callback with key=pyfunc_13 in the registry.\n",
      "Traceback (most recent call last):\n",
      "\n",
      "  File \"D:\\Apps\\anaconda\\envs\\swara\\lib\\site-packages\\tensorflow\\python\\ops\\script_ops.py\", line 256, in __call__\n",
      "    raise ValueError(f\"Could not find callback with key={token} in the \"\n",
      "\n",
      "ValueError: Could not find callback with key=pyfunc_13 in the registry.\n",
      "\n",
      "\n",
      "\t [[{{node model/landmarks_detector_v3/map/while/PyFunc}}]] [Op:__inference_infer_788]\n",
      "Inference error: Graph execution error:\n",
      "\n",
      "Detected at node 'model/landmarks_detector_v3/map/while/PyFunc' defined at (most recent call last):\n",
      "Node: 'model/landmarks_detector_v3/map/while/PyFunc'\n",
      "ValueError: Could not find callback with key=pyfunc_13 in the registry.\n",
      "Traceback (most recent call last):\n",
      "\n",
      "  File \"D:\\Apps\\anaconda\\envs\\swara\\lib\\site-packages\\tensorflow\\python\\ops\\script_ops.py\", line 256, in __call__\n",
      "    raise ValueError(f\"Could not find callback with key={token} in the \"\n",
      "\n",
      "ValueError: Could not find callback with key=pyfunc_13 in the registry.\n",
      "\n",
      "\n",
      "\t [[{{node model/landmarks_detector_v3/map/while/PyFunc}}]] [Op:__inference_infer_788]\n",
      "Inference error: Graph execution error:\n",
      "\n",
      "Detected at node 'model/landmarks_detector_v3/map/while/PyFunc' defined at (most recent call last):\n",
      "Node: 'model/landmarks_detector_v3/map/while/PyFunc'\n",
      "ValueError: Could not find callback with key=pyfunc_13 in the registry.\n",
      "Traceback (most recent call last):\n",
      "\n",
      "  File \"D:\\Apps\\anaconda\\envs\\swara\\lib\\site-packages\\tensorflow\\python\\ops\\script_ops.py\", line 256, in __call__\n",
      "    raise ValueError(f\"Could not find callback with key={token} in the \"\n",
      "\n",
      "ValueError: Could not find callback with key=pyfunc_13 in the registry.\n",
      "\n",
      "\n",
      "\t [[{{node model/landmarks_detector_v3/map/while/PyFunc}}]] [Op:__inference_infer_788]\n",
      "Inference error: Graph execution error:\n",
      "\n",
      "Detected at node 'model/landmarks_detector_v3/map/while/PyFunc' defined at (most recent call last):\n",
      "Node: 'model/landmarks_detector_v3/map/while/PyFunc'\n",
      "ValueError: Could not find callback with key=pyfunc_13 in the registry.\n",
      "Traceback (most recent call last):\n",
      "\n",
      "  File \"D:\\Apps\\anaconda\\envs\\swara\\lib\\site-packages\\tensorflow\\python\\ops\\script_ops.py\", line 256, in __call__\n",
      "    raise ValueError(f\"Could not find callback with key={token} in the \"\n",
      "\n",
      "ValueError: Could not find callback with key=pyfunc_13 in the registry.\n",
      "\n",
      "\n",
      "\t [[{{node model/landmarks_detector_v3/map/while/PyFunc}}]] [Op:__inference_infer_788]\n",
      "Inference error: Graph execution error:\n",
      "\n",
      "Detected at node 'model/landmarks_detector_v3/map/while/PyFunc' defined at (most recent call last):\n",
      "Node: 'model/landmarks_detector_v3/map/while/PyFunc'\n",
      "ValueError: Could not find callback with key=pyfunc_13 in the registry.\n",
      "Traceback (most recent call last):\n",
      "\n",
      "  File \"D:\\Apps\\anaconda\\envs\\swara\\lib\\site-packages\\tensorflow\\python\\ops\\script_ops.py\", line 256, in __call__\n",
      "    raise ValueError(f\"Could not find callback with key={token} in the \"\n",
      "\n",
      "ValueError: Could not find callback with key=pyfunc_13 in the registry.\n",
      "\n",
      "\n",
      "\t [[{{node model/landmarks_detector_v3/map/while/PyFunc}}]] [Op:__inference_infer_788]\n",
      "Inference error: Graph execution error:\n",
      "\n",
      "Detected at node 'model/landmarks_detector_v3/map/while/PyFunc' defined at (most recent call last):\n",
      "Node: 'model/landmarks_detector_v3/map/while/PyFunc'\n",
      "ValueError: Could not find callback with key=pyfunc_13 in the registry.\n",
      "Traceback (most recent call last):\n",
      "\n",
      "  File \"D:\\Apps\\anaconda\\envs\\swara\\lib\\site-packages\\tensorflow\\python\\ops\\script_ops.py\", line 256, in __call__\n",
      "    raise ValueError(f\"Could not find callback with key={token} in the \"\n",
      "\n",
      "ValueError: Could not find callback with key=pyfunc_13 in the registry.\n",
      "\n",
      "\n",
      "\t [[{{node model/landmarks_detector_v3/map/while/PyFunc}}]] [Op:__inference_infer_788]\n",
      "Inference error: Graph execution error:\n",
      "\n",
      "Detected at node 'model/landmarks_detector_v3/map/while/PyFunc' defined at (most recent call last):\n",
      "Node: 'model/landmarks_detector_v3/map/while/PyFunc'\n",
      "ValueError: Could not find callback with key=pyfunc_13 in the registry.\n",
      "Traceback (most recent call last):\n",
      "\n",
      "  File \"D:\\Apps\\anaconda\\envs\\swara\\lib\\site-packages\\tensorflow\\python\\ops\\script_ops.py\", line 256, in __call__\n",
      "    raise ValueError(f\"Could not find callback with key={token} in the \"\n",
      "\n",
      "ValueError: Could not find callback with key=pyfunc_13 in the registry.\n",
      "\n",
      "\n",
      "\t [[{{node model/landmarks_detector_v3/map/while/PyFunc}}]] [Op:__inference_infer_788]\n",
      "Inference error: Graph execution error:\n",
      "\n",
      "Detected at node 'model/landmarks_detector_v3/map/while/PyFunc' defined at (most recent call last):\n",
      "Node: 'model/landmarks_detector_v3/map/while/PyFunc'\n",
      "ValueError: Could not find callback with key=pyfunc_13 in the registry.\n",
      "Traceback (most recent call last):\n",
      "\n",
      "  File \"D:\\Apps\\anaconda\\envs\\swara\\lib\\site-packages\\tensorflow\\python\\ops\\script_ops.py\", line 256, in __call__\n",
      "    raise ValueError(f\"Could not find callback with key={token} in the \"\n",
      "\n",
      "ValueError: Could not find callback with key=pyfunc_13 in the registry.\n",
      "\n",
      "\n",
      "\t [[{{node model/landmarks_detector_v3/map/while/PyFunc}}]] [Op:__inference_infer_788]\n",
      "Inference error: Graph execution error:\n",
      "\n",
      "Detected at node 'model/landmarks_detector_v3/map/while/PyFunc' defined at (most recent call last):\n",
      "Node: 'model/landmarks_detector_v3/map/while/PyFunc'\n",
      "ValueError: Could not find callback with key=pyfunc_13 in the registry.\n",
      "Traceback (most recent call last):\n",
      "\n",
      "  File \"D:\\Apps\\anaconda\\envs\\swara\\lib\\site-packages\\tensorflow\\python\\ops\\script_ops.py\", line 256, in __call__\n",
      "    raise ValueError(f\"Could not find callback with key={token} in the \"\n",
      "\n",
      "ValueError: Could not find callback with key=pyfunc_13 in the registry.\n",
      "\n",
      "\n",
      "\t [[{{node model/landmarks_detector_v3/map/while/PyFunc}}]] [Op:__inference_infer_788]\n",
      "Inference error: Graph execution error:\n",
      "\n",
      "Detected at node 'model/landmarks_detector_v3/map/while/PyFunc' defined at (most recent call last):\n",
      "Node: 'model/landmarks_detector_v3/map/while/PyFunc'\n",
      "ValueError: Could not find callback with key=pyfunc_13 in the registry.\n",
      "Traceback (most recent call last):\n",
      "\n",
      "  File \"D:\\Apps\\anaconda\\envs\\swara\\lib\\site-packages\\tensorflow\\python\\ops\\script_ops.py\", line 256, in __call__\n",
      "    raise ValueError(f\"Could not find callback with key={token} in the \"\n",
      "\n",
      "ValueError: Could not find callback with key=pyfunc_13 in the registry.\n",
      "\n",
      "\n",
      "\t [[{{node model/landmarks_detector_v3/map/while/PyFunc}}]] [Op:__inference_infer_788]\n",
      "Inference error: Graph execution error:\n",
      "\n",
      "Detected at node 'model/landmarks_detector_v3/map/while/PyFunc' defined at (most recent call last):\n",
      "Node: 'model/landmarks_detector_v3/map/while/PyFunc'\n",
      "ValueError: Could not find callback with key=pyfunc_13 in the registry.\n",
      "Traceback (most recent call last):\n",
      "\n",
      "  File \"D:\\Apps\\anaconda\\envs\\swara\\lib\\site-packages\\tensorflow\\python\\ops\\script_ops.py\", line 256, in __call__\n",
      "    raise ValueError(f\"Could not find callback with key={token} in the \"\n",
      "\n",
      "ValueError: Could not find callback with key=pyfunc_13 in the registry.\n",
      "\n",
      "\n",
      "\t [[{{node model/landmarks_detector_v3/map/while/PyFunc}}]] [Op:__inference_infer_788]\n",
      "Inference error: Graph execution error:\n",
      "\n",
      "Detected at node 'model/landmarks_detector_v3/map/while/PyFunc' defined at (most recent call last):\n",
      "Node: 'model/landmarks_detector_v3/map/while/PyFunc'\n",
      "ValueError: Could not find callback with key=pyfunc_13 in the registry.\n",
      "Traceback (most recent call last):\n",
      "\n",
      "  File \"D:\\Apps\\anaconda\\envs\\swara\\lib\\site-packages\\tensorflow\\python\\ops\\script_ops.py\", line 256, in __call__\n",
      "    raise ValueError(f\"Could not find callback with key={token} in the \"\n",
      "\n",
      "ValueError: Could not find callback with key=pyfunc_13 in the registry.\n",
      "\n",
      "\n",
      "\t [[{{node model/landmarks_detector_v3/map/while/PyFunc}}]] [Op:__inference_infer_788]\n",
      "Inference error: Graph execution error:\n",
      "\n",
      "Detected at node 'model/landmarks_detector_v3/map/while/PyFunc' defined at (most recent call last):\n",
      "Node: 'model/landmarks_detector_v3/map/while/PyFunc'\n",
      "ValueError: Could not find callback with key=pyfunc_13 in the registry.\n",
      "Traceback (most recent call last):\n",
      "\n",
      "  File \"D:\\Apps\\anaconda\\envs\\swara\\lib\\site-packages\\tensorflow\\python\\ops\\script_ops.py\", line 256, in __call__\n",
      "    raise ValueError(f\"Could not find callback with key={token} in the \"\n",
      "\n",
      "ValueError: Could not find callback with key=pyfunc_13 in the registry.\n",
      "\n",
      "\n",
      "\t [[{{node model/landmarks_detector_v3/map/while/PyFunc}}]] [Op:__inference_infer_788]\n",
      "Inference error: Graph execution error:\n",
      "\n",
      "Detected at node 'model/landmarks_detector_v3/map/while/PyFunc' defined at (most recent call last):\n",
      "Node: 'model/landmarks_detector_v3/map/while/PyFunc'\n",
      "ValueError: Could not find callback with key=pyfunc_13 in the registry.\n",
      "Traceback (most recent call last):\n",
      "\n",
      "  File \"D:\\Apps\\anaconda\\envs\\swara\\lib\\site-packages\\tensorflow\\python\\ops\\script_ops.py\", line 256, in __call__\n",
      "    raise ValueError(f\"Could not find callback with key={token} in the \"\n",
      "\n",
      "ValueError: Could not find callback with key=pyfunc_13 in the registry.\n",
      "\n",
      "\n",
      "\t [[{{node model/landmarks_detector_v3/map/while/PyFunc}}]] [Op:__inference_infer_788]\n",
      "Inference error: Graph execution error:\n",
      "\n",
      "Detected at node 'model/landmarks_detector_v3/map/while/PyFunc' defined at (most recent call last):\n",
      "Node: 'model/landmarks_detector_v3/map/while/PyFunc'\n",
      "ValueError: Could not find callback with key=pyfunc_13 in the registry.\n",
      "Traceback (most recent call last):\n",
      "\n",
      "  File \"D:\\Apps\\anaconda\\envs\\swara\\lib\\site-packages\\tensorflow\\python\\ops\\script_ops.py\", line 256, in __call__\n",
      "    raise ValueError(f\"Could not find callback with key={token} in the \"\n",
      "\n",
      "ValueError: Could not find callback with key=pyfunc_13 in the registry.\n",
      "\n",
      "\n",
      "\t [[{{node model/landmarks_detector_v3/map/while/PyFunc}}]] [Op:__inference_infer_788]\n",
      "Inference error: Graph execution error:\n",
      "\n",
      "Detected at node 'model/landmarks_detector_v3/map/while/PyFunc' defined at (most recent call last):\n",
      "Node: 'model/landmarks_detector_v3/map/while/PyFunc'\n",
      "ValueError: Could not find callback with key=pyfunc_13 in the registry.\n",
      "Traceback (most recent call last):\n",
      "\n",
      "  File \"D:\\Apps\\anaconda\\envs\\swara\\lib\\site-packages\\tensorflow\\python\\ops\\script_ops.py\", line 256, in __call__\n",
      "    raise ValueError(f\"Could not find callback with key={token} in the \"\n",
      "\n",
      "ValueError: Could not find callback with key=pyfunc_13 in the registry.\n",
      "\n",
      "\n",
      "\t [[{{node model/landmarks_detector_v3/map/while/PyFunc}}]] [Op:__inference_infer_788]\n",
      "Inference error: Graph execution error:\n",
      "\n",
      "Detected at node 'model/landmarks_detector_v3/map/while/PyFunc' defined at (most recent call last):\n",
      "Node: 'model/landmarks_detector_v3/map/while/PyFunc'\n",
      "ValueError: Could not find callback with key=pyfunc_13 in the registry.\n",
      "Traceback (most recent call last):\n",
      "\n",
      "  File \"D:\\Apps\\anaconda\\envs\\swara\\lib\\site-packages\\tensorflow\\python\\ops\\script_ops.py\", line 256, in __call__\n",
      "    raise ValueError(f\"Could not find callback with key={token} in the \"\n",
      "\n",
      "ValueError: Could not find callback with key=pyfunc_13 in the registry.\n",
      "\n",
      "\n",
      "\t [[{{node model/landmarks_detector_v3/map/while/PyFunc}}]] [Op:__inference_infer_788]\n",
      "Inference error: Graph execution error:\n",
      "\n",
      "Detected at node 'model/landmarks_detector_v3/map/while/PyFunc' defined at (most recent call last):\n",
      "Node: 'model/landmarks_detector_v3/map/while/PyFunc'\n",
      "ValueError: Could not find callback with key=pyfunc_13 in the registry.\n",
      "Traceback (most recent call last):\n",
      "\n",
      "  File \"D:\\Apps\\anaconda\\envs\\swara\\lib\\site-packages\\tensorflow\\python\\ops\\script_ops.py\", line 256, in __call__\n",
      "    raise ValueError(f\"Could not find callback with key={token} in the \"\n",
      "\n",
      "ValueError: Could not find callback with key=pyfunc_13 in the registry.\n",
      "\n",
      "\n",
      "\t [[{{node model/landmarks_detector_v3/map/while/PyFunc}}]] [Op:__inference_infer_788]\n",
      "Inference error: Graph execution error:\n",
      "\n",
      "Detected at node 'model/landmarks_detector_v3/map/while/PyFunc' defined at (most recent call last):\n",
      "Node: 'model/landmarks_detector_v3/map/while/PyFunc'\n",
      "ValueError: Could not find callback with key=pyfunc_13 in the registry.\n",
      "Traceback (most recent call last):\n",
      "\n",
      "  File \"D:\\Apps\\anaconda\\envs\\swara\\lib\\site-packages\\tensorflow\\python\\ops\\script_ops.py\", line 256, in __call__\n",
      "    raise ValueError(f\"Could not find callback with key={token} in the \"\n",
      "\n",
      "ValueError: Could not find callback with key=pyfunc_13 in the registry.\n",
      "\n",
      "\n",
      "\t [[{{node model/landmarks_detector_v3/map/while/PyFunc}}]] [Op:__inference_infer_788]\n",
      "Inference error: Graph execution error:\n",
      "\n",
      "Detected at node 'model/landmarks_detector_v3/map/while/PyFunc' defined at (most recent call last):\n",
      "Node: 'model/landmarks_detector_v3/map/while/PyFunc'\n",
      "ValueError: Could not find callback with key=pyfunc_13 in the registry.\n",
      "Traceback (most recent call last):\n",
      "\n",
      "  File \"D:\\Apps\\anaconda\\envs\\swara\\lib\\site-packages\\tensorflow\\python\\ops\\script_ops.py\", line 256, in __call__\n",
      "    raise ValueError(f\"Could not find callback with key={token} in the \"\n",
      "\n",
      "ValueError: Could not find callback with key=pyfunc_13 in the registry.\n",
      "\n",
      "\n",
      "\t [[{{node model/landmarks_detector_v3/map/while/PyFunc}}]] [Op:__inference_infer_788]\n",
      "Inference error: Graph execution error:\n",
      "\n",
      "Detected at node 'model/landmarks_detector_v3/map/while/PyFunc' defined at (most recent call last):\n",
      "Node: 'model/landmarks_detector_v3/map/while/PyFunc'\n",
      "ValueError: Could not find callback with key=pyfunc_13 in the registry.\n",
      "Traceback (most recent call last):\n",
      "\n",
      "  File \"D:\\Apps\\anaconda\\envs\\swara\\lib\\site-packages\\tensorflow\\python\\ops\\script_ops.py\", line 256, in __call__\n",
      "    raise ValueError(f\"Could not find callback with key={token} in the \"\n",
      "\n",
      "ValueError: Could not find callback with key=pyfunc_13 in the registry.\n",
      "\n",
      "\n",
      "\t [[{{node model/landmarks_detector_v3/map/while/PyFunc}}]] [Op:__inference_infer_788]\n",
      "Inference error: Graph execution error:\n",
      "\n",
      "Detected at node 'model/landmarks_detector_v3/map/while/PyFunc' defined at (most recent call last):\n",
      "Node: 'model/landmarks_detector_v3/map/while/PyFunc'\n",
      "ValueError: Could not find callback with key=pyfunc_13 in the registry.\n",
      "Traceback (most recent call last):\n",
      "\n",
      "  File \"D:\\Apps\\anaconda\\envs\\swara\\lib\\site-packages\\tensorflow\\python\\ops\\script_ops.py\", line 256, in __call__\n",
      "    raise ValueError(f\"Could not find callback with key={token} in the \"\n",
      "\n",
      "ValueError: Could not find callback with key=pyfunc_13 in the registry.\n",
      "\n",
      "\n",
      "\t [[{{node model/landmarks_detector_v3/map/while/PyFunc}}]] [Op:__inference_infer_788]\n",
      "Inference error: Graph execution error:\n",
      "\n",
      "Detected at node 'model/landmarks_detector_v3/map/while/PyFunc' defined at (most recent call last):\n",
      "Node: 'model/landmarks_detector_v3/map/while/PyFunc'\n",
      "ValueError: Could not find callback with key=pyfunc_13 in the registry.\n",
      "Traceback (most recent call last):\n",
      "\n",
      "  File \"D:\\Apps\\anaconda\\envs\\swara\\lib\\site-packages\\tensorflow\\python\\ops\\script_ops.py\", line 256, in __call__\n",
      "    raise ValueError(f\"Could not find callback with key={token} in the \"\n",
      "\n",
      "ValueError: Could not find callback with key=pyfunc_13 in the registry.\n",
      "\n",
      "\n",
      "\t [[{{node model/landmarks_detector_v3/map/while/PyFunc}}]] [Op:__inference_infer_788]\n",
      "Inference error: Graph execution error:\n",
      "\n",
      "Detected at node 'model/landmarks_detector_v3/map/while/PyFunc' defined at (most recent call last):\n",
      "Node: 'model/landmarks_detector_v3/map/while/PyFunc'\n",
      "ValueError: Could not find callback with key=pyfunc_13 in the registry.\n",
      "Traceback (most recent call last):\n",
      "\n",
      "  File \"D:\\Apps\\anaconda\\envs\\swara\\lib\\site-packages\\tensorflow\\python\\ops\\script_ops.py\", line 256, in __call__\n",
      "    raise ValueError(f\"Could not find callback with key={token} in the \"\n",
      "\n",
      "ValueError: Could not find callback with key=pyfunc_13 in the registry.\n",
      "\n",
      "\n",
      "\t [[{{node model/landmarks_detector_v3/map/while/PyFunc}}]] [Op:__inference_infer_788]\n",
      "Inference error: Graph execution error:\n",
      "\n",
      "Detected at node 'model/landmarks_detector_v3/map/while/PyFunc' defined at (most recent call last):\n",
      "Node: 'model/landmarks_detector_v3/map/while/PyFunc'\n",
      "ValueError: Could not find callback with key=pyfunc_13 in the registry.\n",
      "Traceback (most recent call last):\n",
      "\n",
      "  File \"D:\\Apps\\anaconda\\envs\\swara\\lib\\site-packages\\tensorflow\\python\\ops\\script_ops.py\", line 256, in __call__\n",
      "    raise ValueError(f\"Could not find callback with key={token} in the \"\n",
      "\n",
      "ValueError: Could not find callback with key=pyfunc_13 in the registry.\n",
      "\n",
      "\n",
      "\t [[{{node model/landmarks_detector_v3/map/while/PyFunc}}]] [Op:__inference_infer_788]\n",
      "Inference error: Graph execution error:\n",
      "\n",
      "Detected at node 'model/landmarks_detector_v3/map/while/PyFunc' defined at (most recent call last):\n",
      "Node: 'model/landmarks_detector_v3/map/while/PyFunc'\n",
      "ValueError: Could not find callback with key=pyfunc_13 in the registry.\n",
      "Traceback (most recent call last):\n",
      "\n",
      "  File \"D:\\Apps\\anaconda\\envs\\swara\\lib\\site-packages\\tensorflow\\python\\ops\\script_ops.py\", line 256, in __call__\n",
      "    raise ValueError(f\"Could not find callback with key={token} in the \"\n",
      "\n",
      "ValueError: Could not find callback with key=pyfunc_13 in the registry.\n",
      "\n",
      "\n",
      "\t [[{{node model/landmarks_detector_v3/map/while/PyFunc}}]] [Op:__inference_infer_788]\n",
      "Inference error: Graph execution error:\n",
      "\n",
      "Detected at node 'model/landmarks_detector_v3/map/while/PyFunc' defined at (most recent call last):\n",
      "Node: 'model/landmarks_detector_v3/map/while/PyFunc'\n",
      "ValueError: Could not find callback with key=pyfunc_13 in the registry.\n",
      "Traceback (most recent call last):\n",
      "\n",
      "  File \"D:\\Apps\\anaconda\\envs\\swara\\lib\\site-packages\\tensorflow\\python\\ops\\script_ops.py\", line 256, in __call__\n",
      "    raise ValueError(f\"Could not find callback with key={token} in the \"\n",
      "\n",
      "ValueError: Could not find callback with key=pyfunc_13 in the registry.\n",
      "\n",
      "\n",
      "\t [[{{node model/landmarks_detector_v3/map/while/PyFunc}}]] [Op:__inference_infer_788]\n",
      "Inference error: Graph execution error:\n",
      "\n",
      "Detected at node 'model/landmarks_detector_v3/map/while/PyFunc' defined at (most recent call last):\n",
      "Node: 'model/landmarks_detector_v3/map/while/PyFunc'\n",
      "ValueError: Could not find callback with key=pyfunc_13 in the registry.\n",
      "Traceback (most recent call last):\n",
      "\n",
      "  File \"D:\\Apps\\anaconda\\envs\\swara\\lib\\site-packages\\tensorflow\\python\\ops\\script_ops.py\", line 256, in __call__\n",
      "    raise ValueError(f\"Could not find callback with key={token} in the \"\n",
      "\n",
      "ValueError: Could not find callback with key=pyfunc_13 in the registry.\n",
      "\n",
      "\n",
      "\t [[{{node model/landmarks_detector_v3/map/while/PyFunc}}]] [Op:__inference_infer_788]\n",
      "Inference error: Graph execution error:\n",
      "\n",
      "Detected at node 'model/landmarks_detector_v3/map/while/PyFunc' defined at (most recent call last):\n",
      "Node: 'model/landmarks_detector_v3/map/while/PyFunc'\n",
      "ValueError: Could not find callback with key=pyfunc_13 in the registry.\n",
      "Traceback (most recent call last):\n",
      "\n",
      "  File \"D:\\Apps\\anaconda\\envs\\swara\\lib\\site-packages\\tensorflow\\python\\ops\\script_ops.py\", line 256, in __call__\n",
      "    raise ValueError(f\"Could not find callback with key={token} in the \"\n",
      "\n",
      "ValueError: Could not find callback with key=pyfunc_13 in the registry.\n",
      "\n",
      "\n",
      "\t [[{{node model/landmarks_detector_v3/map/while/PyFunc}}]] [Op:__inference_infer_788]\n",
      "Inference error: Graph execution error:\n",
      "\n",
      "Detected at node 'model/landmarks_detector_v3/map/while/PyFunc' defined at (most recent call last):\n",
      "Node: 'model/landmarks_detector_v3/map/while/PyFunc'\n",
      "ValueError: Could not find callback with key=pyfunc_13 in the registry.\n",
      "Traceback (most recent call last):\n",
      "\n",
      "  File \"D:\\Apps\\anaconda\\envs\\swara\\lib\\site-packages\\tensorflow\\python\\ops\\script_ops.py\", line 256, in __call__\n",
      "    raise ValueError(f\"Could not find callback with key={token} in the \"\n",
      "\n",
      "ValueError: Could not find callback with key=pyfunc_13 in the registry.\n",
      "\n",
      "\n",
      "\t [[{{node model/landmarks_detector_v3/map/while/PyFunc}}]] [Op:__inference_infer_788]\n",
      "Inference error: Graph execution error:\n",
      "\n",
      "Detected at node 'model/landmarks_detector_v3/map/while/PyFunc' defined at (most recent call last):\n",
      "Node: 'model/landmarks_detector_v3/map/while/PyFunc'\n",
      "ValueError: Could not find callback with key=pyfunc_13 in the registry.\n",
      "Traceback (most recent call last):\n",
      "\n",
      "  File \"D:\\Apps\\anaconda\\envs\\swara\\lib\\site-packages\\tensorflow\\python\\ops\\script_ops.py\", line 256, in __call__\n",
      "    raise ValueError(f\"Could not find callback with key={token} in the \"\n",
      "\n",
      "ValueError: Could not find callback with key=pyfunc_13 in the registry.\n",
      "\n",
      "\n",
      "\t [[{{node model/landmarks_detector_v3/map/while/PyFunc}}]] [Op:__inference_infer_788]\n",
      "Inference error: Graph execution error:\n",
      "\n",
      "Detected at node 'model/landmarks_detector_v3/map/while/PyFunc' defined at (most recent call last):\n",
      "Node: 'model/landmarks_detector_v3/map/while/PyFunc'\n",
      "ValueError: Could not find callback with key=pyfunc_13 in the registry.\n",
      "Traceback (most recent call last):\n",
      "\n",
      "  File \"D:\\Apps\\anaconda\\envs\\swara\\lib\\site-packages\\tensorflow\\python\\ops\\script_ops.py\", line 256, in __call__\n",
      "    raise ValueError(f\"Could not find callback with key={token} in the \"\n",
      "\n",
      "ValueError: Could not find callback with key=pyfunc_13 in the registry.\n",
      "\n",
      "\n",
      "\t [[{{node model/landmarks_detector_v3/map/while/PyFunc}}]] [Op:__inference_infer_788]\n",
      "Inference error: Graph execution error:\n",
      "\n",
      "Detected at node 'model/landmarks_detector_v3/map/while/PyFunc' defined at (most recent call last):\n",
      "Node: 'model/landmarks_detector_v3/map/while/PyFunc'\n",
      "ValueError: Could not find callback with key=pyfunc_13 in the registry.\n",
      "Traceback (most recent call last):\n",
      "\n",
      "  File \"D:\\Apps\\anaconda\\envs\\swara\\lib\\site-packages\\tensorflow\\python\\ops\\script_ops.py\", line 256, in __call__\n",
      "    raise ValueError(f\"Could not find callback with key={token} in the \"\n",
      "\n",
      "ValueError: Could not find callback with key=pyfunc_13 in the registry.\n",
      "\n",
      "\n",
      "\t [[{{node model/landmarks_detector_v3/map/while/PyFunc}}]] [Op:__inference_infer_788]\n",
      "Inference error: Graph execution error:\n",
      "\n",
      "Detected at node 'model/landmarks_detector_v3/map/while/PyFunc' defined at (most recent call last):\n",
      "Node: 'model/landmarks_detector_v3/map/while/PyFunc'\n",
      "ValueError: Could not find callback with key=pyfunc_13 in the registry.\n",
      "Traceback (most recent call last):\n",
      "\n",
      "  File \"D:\\Apps\\anaconda\\envs\\swara\\lib\\site-packages\\tensorflow\\python\\ops\\script_ops.py\", line 256, in __call__\n",
      "    raise ValueError(f\"Could not find callback with key={token} in the \"\n",
      "\n",
      "ValueError: Could not find callback with key=pyfunc_13 in the registry.\n",
      "\n",
      "\n",
      "\t [[{{node model/landmarks_detector_v3/map/while/PyFunc}}]] [Op:__inference_infer_788]\n",
      "Inference error: Graph execution error:\n",
      "\n",
      "Detected at node 'model/landmarks_detector_v3/map/while/PyFunc' defined at (most recent call last):\n",
      "Node: 'model/landmarks_detector_v3/map/while/PyFunc'\n",
      "ValueError: Could not find callback with key=pyfunc_13 in the registry.\n",
      "Traceback (most recent call last):\n",
      "\n",
      "  File \"D:\\Apps\\anaconda\\envs\\swara\\lib\\site-packages\\tensorflow\\python\\ops\\script_ops.py\", line 256, in __call__\n",
      "    raise ValueError(f\"Could not find callback with key={token} in the \"\n",
      "\n",
      "ValueError: Could not find callback with key=pyfunc_13 in the registry.\n",
      "\n",
      "\n",
      "\t [[{{node model/landmarks_detector_v3/map/while/PyFunc}}]] [Op:__inference_infer_788]\n",
      "Inference error: Graph execution error:\n",
      "\n",
      "Detected at node 'model/landmarks_detector_v3/map/while/PyFunc' defined at (most recent call last):\n",
      "Node: 'model/landmarks_detector_v3/map/while/PyFunc'\n",
      "ValueError: Could not find callback with key=pyfunc_13 in the registry.\n",
      "Traceback (most recent call last):\n",
      "\n",
      "  File \"D:\\Apps\\anaconda\\envs\\swara\\lib\\site-packages\\tensorflow\\python\\ops\\script_ops.py\", line 256, in __call__\n",
      "    raise ValueError(f\"Could not find callback with key={token} in the \"\n",
      "\n",
      "ValueError: Could not find callback with key=pyfunc_13 in the registry.\n",
      "\n",
      "\n",
      "\t [[{{node model/landmarks_detector_v3/map/while/PyFunc}}]] [Op:__inference_infer_788]\n",
      "Inference error: Graph execution error:\n",
      "\n",
      "Detected at node 'model/landmarks_detector_v3/map/while/PyFunc' defined at (most recent call last):\n",
      "Node: 'model/landmarks_detector_v3/map/while/PyFunc'\n",
      "ValueError: Could not find callback with key=pyfunc_13 in the registry.\n",
      "Traceback (most recent call last):\n",
      "\n",
      "  File \"D:\\Apps\\anaconda\\envs\\swara\\lib\\site-packages\\tensorflow\\python\\ops\\script_ops.py\", line 256, in __call__\n",
      "    raise ValueError(f\"Could not find callback with key={token} in the \"\n",
      "\n",
      "ValueError: Could not find callback with key=pyfunc_13 in the registry.\n",
      "\n",
      "\n",
      "\t [[{{node model/landmarks_detector_v3/map/while/PyFunc}}]] [Op:__inference_infer_788]\n",
      "Inference error: Graph execution error:\n",
      "\n",
      "Detected at node 'model/landmarks_detector_v3/map/while/PyFunc' defined at (most recent call last):\n",
      "Node: 'model/landmarks_detector_v3/map/while/PyFunc'\n",
      "ValueError: Could not find callback with key=pyfunc_13 in the registry.\n",
      "Traceback (most recent call last):\n",
      "\n",
      "  File \"D:\\Apps\\anaconda\\envs\\swara\\lib\\site-packages\\tensorflow\\python\\ops\\script_ops.py\", line 256, in __call__\n",
      "    raise ValueError(f\"Could not find callback with key={token} in the \"\n",
      "\n",
      "ValueError: Could not find callback with key=pyfunc_13 in the registry.\n",
      "\n",
      "\n",
      "\t [[{{node model/landmarks_detector_v3/map/while/PyFunc}}]] [Op:__inference_infer_788]\n",
      "Inference error: Graph execution error:\n",
      "\n",
      "Detected at node 'model/landmarks_detector_v3/map/while/PyFunc' defined at (most recent call last):\n",
      "Node: 'model/landmarks_detector_v3/map/while/PyFunc'\n",
      "ValueError: Could not find callback with key=pyfunc_13 in the registry.\n",
      "Traceback (most recent call last):\n",
      "\n",
      "  File \"D:\\Apps\\anaconda\\envs\\swara\\lib\\site-packages\\tensorflow\\python\\ops\\script_ops.py\", line 256, in __call__\n",
      "    raise ValueError(f\"Could not find callback with key={token} in the \"\n",
      "\n",
      "ValueError: Could not find callback with key=pyfunc_13 in the registry.\n",
      "\n",
      "\n",
      "\t [[{{node model/landmarks_detector_v3/map/while/PyFunc}}]] [Op:__inference_infer_788]\n",
      "Inference error: Graph execution error:\n",
      "\n",
      "Detected at node 'model/landmarks_detector_v3/map/while/PyFunc' defined at (most recent call last):\n",
      "Node: 'model/landmarks_detector_v3/map/while/PyFunc'\n",
      "ValueError: Could not find callback with key=pyfunc_13 in the registry.\n",
      "Traceback (most recent call last):\n",
      "\n",
      "  File \"D:\\Apps\\anaconda\\envs\\swara\\lib\\site-packages\\tensorflow\\python\\ops\\script_ops.py\", line 256, in __call__\n",
      "    raise ValueError(f\"Could not find callback with key={token} in the \"\n",
      "\n",
      "ValueError: Could not find callback with key=pyfunc_13 in the registry.\n",
      "\n",
      "\n",
      "\t [[{{node model/landmarks_detector_v3/map/while/PyFunc}}]] [Op:__inference_infer_788]\n",
      "Inference error: Graph execution error:\n",
      "\n",
      "Detected at node 'model/landmarks_detector_v3/map/while/PyFunc' defined at (most recent call last):\n",
      "Node: 'model/landmarks_detector_v3/map/while/PyFunc'\n",
      "ValueError: Could not find callback with key=pyfunc_13 in the registry.\n",
      "Traceback (most recent call last):\n",
      "\n",
      "  File \"D:\\Apps\\anaconda\\envs\\swara\\lib\\site-packages\\tensorflow\\python\\ops\\script_ops.py\", line 256, in __call__\n",
      "    raise ValueError(f\"Could not find callback with key={token} in the \"\n",
      "\n",
      "ValueError: Could not find callback with key=pyfunc_13 in the registry.\n",
      "\n",
      "\n",
      "\t [[{{node model/landmarks_detector_v3/map/while/PyFunc}}]] [Op:__inference_infer_788]\n",
      "Inference error: Graph execution error:\n",
      "\n",
      "Detected at node 'model/landmarks_detector_v3/map/while/PyFunc' defined at (most recent call last):\n",
      "Node: 'model/landmarks_detector_v3/map/while/PyFunc'\n",
      "ValueError: Could not find callback with key=pyfunc_13 in the registry.\n",
      "Traceback (most recent call last):\n",
      "\n",
      "  File \"D:\\Apps\\anaconda\\envs\\swara\\lib\\site-packages\\tensorflow\\python\\ops\\script_ops.py\", line 256, in __call__\n",
      "    raise ValueError(f\"Could not find callback with key={token} in the \"\n",
      "\n",
      "ValueError: Could not find callback with key=pyfunc_13 in the registry.\n",
      "\n",
      "\n",
      "\t [[{{node model/landmarks_detector_v3/map/while/PyFunc}}]] [Op:__inference_infer_788]\n",
      "Inference error: Graph execution error:\n",
      "\n",
      "Detected at node 'model/landmarks_detector_v3/map/while/PyFunc' defined at (most recent call last):\n",
      "Node: 'model/landmarks_detector_v3/map/while/PyFunc'\n",
      "ValueError: Could not find callback with key=pyfunc_13 in the registry.\n",
      "Traceback (most recent call last):\n",
      "\n",
      "  File \"D:\\Apps\\anaconda\\envs\\swara\\lib\\site-packages\\tensorflow\\python\\ops\\script_ops.py\", line 256, in __call__\n",
      "    raise ValueError(f\"Could not find callback with key={token} in the \"\n",
      "\n",
      "ValueError: Could not find callback with key=pyfunc_13 in the registry.\n",
      "\n",
      "\n",
      "\t [[{{node model/landmarks_detector_v3/map/while/PyFunc}}]] [Op:__inference_infer_788]\n",
      "Inference error: Graph execution error:\n",
      "\n",
      "Detected at node 'model/landmarks_detector_v3/map/while/PyFunc' defined at (most recent call last):\n",
      "Node: 'model/landmarks_detector_v3/map/while/PyFunc'\n",
      "ValueError: Could not find callback with key=pyfunc_13 in the registry.\n",
      "Traceback (most recent call last):\n",
      "\n",
      "  File \"D:\\Apps\\anaconda\\envs\\swara\\lib\\site-packages\\tensorflow\\python\\ops\\script_ops.py\", line 256, in __call__\n",
      "    raise ValueError(f\"Could not find callback with key={token} in the \"\n",
      "\n",
      "ValueError: Could not find callback with key=pyfunc_13 in the registry.\n",
      "\n",
      "\n",
      "\t [[{{node model/landmarks_detector_v3/map/while/PyFunc}}]] [Op:__inference_infer_788]\n",
      "Inference error: Graph execution error:\n",
      "\n",
      "Detected at node 'model/landmarks_detector_v3/map/while/PyFunc' defined at (most recent call last):\n",
      "Node: 'model/landmarks_detector_v3/map/while/PyFunc'\n",
      "ValueError: Could not find callback with key=pyfunc_13 in the registry.\n",
      "Traceback (most recent call last):\n",
      "\n",
      "  File \"D:\\Apps\\anaconda\\envs\\swara\\lib\\site-packages\\tensorflow\\python\\ops\\script_ops.py\", line 256, in __call__\n",
      "    raise ValueError(f\"Could not find callback with key={token} in the \"\n",
      "\n",
      "ValueError: Could not find callback with key=pyfunc_13 in the registry.\n",
      "\n",
      "\n",
      "\t [[{{node model/landmarks_detector_v3/map/while/PyFunc}}]] [Op:__inference_infer_788]\n",
      "Inference error: Graph execution error:\n",
      "\n",
      "Detected at node 'model/landmarks_detector_v3/map/while/PyFunc' defined at (most recent call last):\n",
      "Node: 'model/landmarks_detector_v3/map/while/PyFunc'\n",
      "ValueError: Could not find callback with key=pyfunc_13 in the registry.\n",
      "Traceback (most recent call last):\n",
      "\n",
      "  File \"D:\\Apps\\anaconda\\envs\\swara\\lib\\site-packages\\tensorflow\\python\\ops\\script_ops.py\", line 256, in __call__\n",
      "    raise ValueError(f\"Could not find callback with key={token} in the \"\n",
      "\n",
      "ValueError: Could not find callback with key=pyfunc_13 in the registry.\n",
      "\n",
      "\n",
      "\t [[{{node model/landmarks_detector_v3/map/while/PyFunc}}]] [Op:__inference_infer_788]\n",
      "Inference error: Graph execution error:\n",
      "\n",
      "Detected at node 'model/landmarks_detector_v3/map/while/PyFunc' defined at (most recent call last):\n",
      "Node: 'model/landmarks_detector_v3/map/while/PyFunc'\n",
      "ValueError: Could not find callback with key=pyfunc_13 in the registry.\n",
      "Traceback (most recent call last):\n",
      "\n",
      "  File \"D:\\Apps\\anaconda\\envs\\swara\\lib\\site-packages\\tensorflow\\python\\ops\\script_ops.py\", line 256, in __call__\n",
      "    raise ValueError(f\"Could not find callback with key={token} in the \"\n",
      "\n",
      "ValueError: Could not find callback with key=pyfunc_13 in the registry.\n",
      "\n",
      "\n",
      "\t [[{{node model/landmarks_detector_v3/map/while/PyFunc}}]] [Op:__inference_infer_788]\n",
      "Inference error: Graph execution error:\n",
      "\n",
      "Detected at node 'model/landmarks_detector_v3/map/while/PyFunc' defined at (most recent call last):\n",
      "Node: 'model/landmarks_detector_v3/map/while/PyFunc'\n",
      "ValueError: Could not find callback with key=pyfunc_13 in the registry.\n",
      "Traceback (most recent call last):\n",
      "\n",
      "  File \"D:\\Apps\\anaconda\\envs\\swara\\lib\\site-packages\\tensorflow\\python\\ops\\script_ops.py\", line 256, in __call__\n",
      "    raise ValueError(f\"Could not find callback with key={token} in the \"\n",
      "\n",
      "ValueError: Could not find callback with key=pyfunc_13 in the registry.\n",
      "\n",
      "\n",
      "\t [[{{node model/landmarks_detector_v3/map/while/PyFunc}}]] [Op:__inference_infer_788]\n",
      "Inference error: Graph execution error:\n",
      "\n",
      "Detected at node 'model/landmarks_detector_v3/map/while/PyFunc' defined at (most recent call last):\n",
      "Node: 'model/landmarks_detector_v3/map/while/PyFunc'\n",
      "ValueError: Could not find callback with key=pyfunc_13 in the registry.\n",
      "Traceback (most recent call last):\n",
      "\n",
      "  File \"D:\\Apps\\anaconda\\envs\\swara\\lib\\site-packages\\tensorflow\\python\\ops\\script_ops.py\", line 256, in __call__\n",
      "    raise ValueError(f\"Could not find callback with key={token} in the \"\n",
      "\n",
      "ValueError: Could not find callback with key=pyfunc_13 in the registry.\n",
      "\n",
      "\n",
      "\t [[{{node model/landmarks_detector_v3/map/while/PyFunc}}]] [Op:__inference_infer_788]\n",
      "Inference error: Graph execution error:\n",
      "\n",
      "Detected at node 'model/landmarks_detector_v3/map/while/PyFunc' defined at (most recent call last):\n",
      "Node: 'model/landmarks_detector_v3/map/while/PyFunc'\n",
      "ValueError: Could not find callback with key=pyfunc_13 in the registry.\n",
      "Traceback (most recent call last):\n",
      "\n",
      "  File \"D:\\Apps\\anaconda\\envs\\swara\\lib\\site-packages\\tensorflow\\python\\ops\\script_ops.py\", line 256, in __call__\n",
      "    raise ValueError(f\"Could not find callback with key={token} in the \"\n",
      "\n",
      "ValueError: Could not find callback with key=pyfunc_13 in the registry.\n",
      "\n",
      "\n",
      "\t [[{{node model/landmarks_detector_v3/map/while/PyFunc}}]] [Op:__inference_infer_788]\n",
      "Inference error: Graph execution error:\n",
      "\n",
      "Detected at node 'model/landmarks_detector_v3/map/while/PyFunc' defined at (most recent call last):\n",
      "Node: 'model/landmarks_detector_v3/map/while/PyFunc'\n",
      "ValueError: Could not find callback with key=pyfunc_13 in the registry.\n",
      "Traceback (most recent call last):\n",
      "\n",
      "  File \"D:\\Apps\\anaconda\\envs\\swara\\lib\\site-packages\\tensorflow\\python\\ops\\script_ops.py\", line 256, in __call__\n",
      "    raise ValueError(f\"Could not find callback with key={token} in the \"\n",
      "\n",
      "ValueError: Could not find callback with key=pyfunc_13 in the registry.\n",
      "\n",
      "\n",
      "\t [[{{node model/landmarks_detector_v3/map/while/PyFunc}}]] [Op:__inference_infer_788]\n",
      "Inference error: Graph execution error:\n",
      "\n",
      "Detected at node 'model/landmarks_detector_v3/map/while/PyFunc' defined at (most recent call last):\n",
      "Node: 'model/landmarks_detector_v3/map/while/PyFunc'\n",
      "ValueError: Could not find callback with key=pyfunc_13 in the registry.\n",
      "Traceback (most recent call last):\n",
      "\n",
      "  File \"D:\\Apps\\anaconda\\envs\\swara\\lib\\site-packages\\tensorflow\\python\\ops\\script_ops.py\", line 256, in __call__\n",
      "    raise ValueError(f\"Could not find callback with key={token} in the \"\n",
      "\n",
      "ValueError: Could not find callback with key=pyfunc_13 in the registry.\n",
      "\n",
      "\n",
      "\t [[{{node model/landmarks_detector_v3/map/while/PyFunc}}]] [Op:__inference_infer_788]\n",
      "Inference error: Graph execution error:\n",
      "\n",
      "Detected at node 'model/landmarks_detector_v3/map/while/PyFunc' defined at (most recent call last):\n",
      "Node: 'model/landmarks_detector_v3/map/while/PyFunc'\n",
      "ValueError: Could not find callback with key=pyfunc_13 in the registry.\n",
      "Traceback (most recent call last):\n",
      "\n",
      "  File \"D:\\Apps\\anaconda\\envs\\swara\\lib\\site-packages\\tensorflow\\python\\ops\\script_ops.py\", line 256, in __call__\n",
      "    raise ValueError(f\"Could not find callback with key={token} in the \"\n",
      "\n",
      "ValueError: Could not find callback with key=pyfunc_13 in the registry.\n",
      "\n",
      "\n",
      "\t [[{{node model/landmarks_detector_v3/map/while/PyFunc}}]] [Op:__inference_infer_788]\n",
      "Inference error: Graph execution error:\n",
      "\n",
      "Detected at node 'model/landmarks_detector_v3/map/while/PyFunc' defined at (most recent call last):\n",
      "Node: 'model/landmarks_detector_v3/map/while/PyFunc'\n",
      "ValueError: Could not find callback with key=pyfunc_13 in the registry.\n",
      "Traceback (most recent call last):\n",
      "\n",
      "  File \"D:\\Apps\\anaconda\\envs\\swara\\lib\\site-packages\\tensorflow\\python\\ops\\script_ops.py\", line 256, in __call__\n",
      "    raise ValueError(f\"Could not find callback with key={token} in the \"\n",
      "\n",
      "ValueError: Could not find callback with key=pyfunc_13 in the registry.\n",
      "\n",
      "\n",
      "\t [[{{node model/landmarks_detector_v3/map/while/PyFunc}}]] [Op:__inference_infer_788]\n",
      "Inference error: Graph execution error:\n",
      "\n",
      "Detected at node 'model/landmarks_detector_v3/map/while/PyFunc' defined at (most recent call last):\n",
      "Node: 'model/landmarks_detector_v3/map/while/PyFunc'\n",
      "ValueError: Could not find callback with key=pyfunc_13 in the registry.\n",
      "Traceback (most recent call last):\n",
      "\n",
      "  File \"D:\\Apps\\anaconda\\envs\\swara\\lib\\site-packages\\tensorflow\\python\\ops\\script_ops.py\", line 256, in __call__\n",
      "    raise ValueError(f\"Could not find callback with key={token} in the \"\n",
      "\n",
      "ValueError: Could not find callback with key=pyfunc_13 in the registry.\n",
      "\n",
      "\n",
      "\t [[{{node model/landmarks_detector_v3/map/while/PyFunc}}]] [Op:__inference_infer_788]\n",
      "Inference error: Graph execution error:\n",
      "\n",
      "Detected at node 'model/landmarks_detector_v3/map/while/PyFunc' defined at (most recent call last):\n",
      "Node: 'model/landmarks_detector_v3/map/while/PyFunc'\n",
      "ValueError: Could not find callback with key=pyfunc_13 in the registry.\n",
      "Traceback (most recent call last):\n",
      "\n",
      "  File \"D:\\Apps\\anaconda\\envs\\swara\\lib\\site-packages\\tensorflow\\python\\ops\\script_ops.py\", line 256, in __call__\n",
      "    raise ValueError(f\"Could not find callback with key={token} in the \"\n",
      "\n",
      "ValueError: Could not find callback with key=pyfunc_13 in the registry.\n",
      "\n",
      "\n",
      "\t [[{{node model/landmarks_detector_v3/map/while/PyFunc}}]] [Op:__inference_infer_788]\n",
      "Inference error: Graph execution error:\n",
      "\n",
      "Detected at node 'model/landmarks_detector_v3/map/while/PyFunc' defined at (most recent call last):\n",
      "Node: 'model/landmarks_detector_v3/map/while/PyFunc'\n",
      "ValueError: Could not find callback with key=pyfunc_13 in the registry.\n",
      "Traceback (most recent call last):\n",
      "\n",
      "  File \"D:\\Apps\\anaconda\\envs\\swara\\lib\\site-packages\\tensorflow\\python\\ops\\script_ops.py\", line 256, in __call__\n",
      "    raise ValueError(f\"Could not find callback with key={token} in the \"\n",
      "\n",
      "ValueError: Could not find callback with key=pyfunc_13 in the registry.\n",
      "\n",
      "\n",
      "\t [[{{node model/landmarks_detector_v3/map/while/PyFunc}}]] [Op:__inference_infer_788]\n",
      "Inference error: Graph execution error:\n",
      "\n",
      "Detected at node 'model/landmarks_detector_v3/map/while/PyFunc' defined at (most recent call last):\n",
      "Node: 'model/landmarks_detector_v3/map/while/PyFunc'\n",
      "ValueError: Could not find callback with key=pyfunc_13 in the registry.\n",
      "Traceback (most recent call last):\n",
      "\n",
      "  File \"D:\\Apps\\anaconda\\envs\\swara\\lib\\site-packages\\tensorflow\\python\\ops\\script_ops.py\", line 256, in __call__\n",
      "    raise ValueError(f\"Could not find callback with key={token} in the \"\n",
      "\n",
      "ValueError: Could not find callback with key=pyfunc_13 in the registry.\n",
      "\n",
      "\n",
      "\t [[{{node model/landmarks_detector_v3/map/while/PyFunc}}]] [Op:__inference_infer_788]\n",
      "Inference error: Graph execution error:\n",
      "\n",
      "Detected at node 'model/landmarks_detector_v3/map/while/PyFunc' defined at (most recent call last):\n",
      "Node: 'model/landmarks_detector_v3/map/while/PyFunc'\n",
      "ValueError: Could not find callback with key=pyfunc_13 in the registry.\n",
      "Traceback (most recent call last):\n",
      "\n",
      "  File \"D:\\Apps\\anaconda\\envs\\swara\\lib\\site-packages\\tensorflow\\python\\ops\\script_ops.py\", line 256, in __call__\n",
      "    raise ValueError(f\"Could not find callback with key={token} in the \"\n",
      "\n",
      "ValueError: Could not find callback with key=pyfunc_13 in the registry.\n",
      "\n",
      "\n",
      "\t [[{{node model/landmarks_detector_v3/map/while/PyFunc}}]] [Op:__inference_infer_788]\n",
      "Inference error: Graph execution error:\n",
      "\n",
      "Detected at node 'model/landmarks_detector_v3/map/while/PyFunc' defined at (most recent call last):\n",
      "Node: 'model/landmarks_detector_v3/map/while/PyFunc'\n",
      "ValueError: Could not find callback with key=pyfunc_13 in the registry.\n",
      "Traceback (most recent call last):\n",
      "\n",
      "  File \"D:\\Apps\\anaconda\\envs\\swara\\lib\\site-packages\\tensorflow\\python\\ops\\script_ops.py\", line 256, in __call__\n",
      "    raise ValueError(f\"Could not find callback with key={token} in the \"\n",
      "\n",
      "ValueError: Could not find callback with key=pyfunc_13 in the registry.\n",
      "\n",
      "\n",
      "\t [[{{node model/landmarks_detector_v3/map/while/PyFunc}}]] [Op:__inference_infer_788]\n",
      "Inference error: Graph execution error:\n",
      "\n",
      "Detected at node 'model/landmarks_detector_v3/map/while/PyFunc' defined at (most recent call last):\n",
      "Node: 'model/landmarks_detector_v3/map/while/PyFunc'\n",
      "ValueError: Could not find callback with key=pyfunc_13 in the registry.\n",
      "Traceback (most recent call last):\n",
      "\n",
      "  File \"D:\\Apps\\anaconda\\envs\\swara\\lib\\site-packages\\tensorflow\\python\\ops\\script_ops.py\", line 256, in __call__\n",
      "    raise ValueError(f\"Could not find callback with key={token} in the \"\n",
      "\n",
      "ValueError: Could not find callback with key=pyfunc_13 in the registry.\n",
      "\n",
      "\n",
      "\t [[{{node model/landmarks_detector_v3/map/while/PyFunc}}]] [Op:__inference_infer_788]\n",
      "Inference error: Graph execution error:\n",
      "\n",
      "Detected at node 'model/landmarks_detector_v3/map/while/PyFunc' defined at (most recent call last):\n",
      "Node: 'model/landmarks_detector_v3/map/while/PyFunc'\n",
      "ValueError: Could not find callback with key=pyfunc_13 in the registry.\n",
      "Traceback (most recent call last):\n",
      "\n",
      "  File \"D:\\Apps\\anaconda\\envs\\swara\\lib\\site-packages\\tensorflow\\python\\ops\\script_ops.py\", line 256, in __call__\n",
      "    raise ValueError(f\"Could not find callback with key={token} in the \"\n",
      "\n",
      "ValueError: Could not find callback with key=pyfunc_13 in the registry.\n",
      "\n",
      "\n",
      "\t [[{{node model/landmarks_detector_v3/map/while/PyFunc}}]] [Op:__inference_infer_788]\n",
      "Inference error: Graph execution error:\n",
      "\n",
      "Detected at node 'model/landmarks_detector_v3/map/while/PyFunc' defined at (most recent call last):\n",
      "Node: 'model/landmarks_detector_v3/map/while/PyFunc'\n",
      "ValueError: Could not find callback with key=pyfunc_13 in the registry.\n",
      "Traceback (most recent call last):\n",
      "\n",
      "  File \"D:\\Apps\\anaconda\\envs\\swara\\lib\\site-packages\\tensorflow\\python\\ops\\script_ops.py\", line 256, in __call__\n",
      "    raise ValueError(f\"Could not find callback with key={token} in the \"\n",
      "\n",
      "ValueError: Could not find callback with key=pyfunc_13 in the registry.\n",
      "\n",
      "\n",
      "\t [[{{node model/landmarks_detector_v3/map/while/PyFunc}}]] [Op:__inference_infer_788]\n",
      "Inference error: Graph execution error:\n",
      "\n",
      "Detected at node 'model/landmarks_detector_v3/map/while/PyFunc' defined at (most recent call last):\n",
      "Node: 'model/landmarks_detector_v3/map/while/PyFunc'\n",
      "ValueError: Could not find callback with key=pyfunc_13 in the registry.\n",
      "Traceback (most recent call last):\n",
      "\n",
      "  File \"D:\\Apps\\anaconda\\envs\\swara\\lib\\site-packages\\tensorflow\\python\\ops\\script_ops.py\", line 256, in __call__\n",
      "    raise ValueError(f\"Could not find callback with key={token} in the \"\n",
      "\n",
      "ValueError: Could not find callback with key=pyfunc_13 in the registry.\n",
      "\n",
      "\n",
      "\t [[{{node model/landmarks_detector_v3/map/while/PyFunc}}]] [Op:__inference_infer_788]\n",
      "Inference error: Graph execution error:\n",
      "\n",
      "Detected at node 'model/landmarks_detector_v3/map/while/PyFunc' defined at (most recent call last):\n",
      "Node: 'model/landmarks_detector_v3/map/while/PyFunc'\n",
      "ValueError: Could not find callback with key=pyfunc_13 in the registry.\n",
      "Traceback (most recent call last):\n",
      "\n",
      "  File \"D:\\Apps\\anaconda\\envs\\swara\\lib\\site-packages\\tensorflow\\python\\ops\\script_ops.py\", line 256, in __call__\n",
      "    raise ValueError(f\"Could not find callback with key={token} in the \"\n",
      "\n",
      "ValueError: Could not find callback with key=pyfunc_13 in the registry.\n",
      "\n",
      "\n",
      "\t [[{{node model/landmarks_detector_v3/map/while/PyFunc}}]] [Op:__inference_infer_788]\n",
      "Inference error: Graph execution error:\n",
      "\n",
      "Detected at node 'model/landmarks_detector_v3/map/while/PyFunc' defined at (most recent call last):\n",
      "Node: 'model/landmarks_detector_v3/map/while/PyFunc'\n",
      "ValueError: Could not find callback with key=pyfunc_13 in the registry.\n",
      "Traceback (most recent call last):\n",
      "\n",
      "  File \"D:\\Apps\\anaconda\\envs\\swara\\lib\\site-packages\\tensorflow\\python\\ops\\script_ops.py\", line 256, in __call__\n",
      "    raise ValueError(f\"Could not find callback with key={token} in the \"\n",
      "\n",
      "ValueError: Could not find callback with key=pyfunc_13 in the registry.\n",
      "\n",
      "\n",
      "\t [[{{node model/landmarks_detector_v3/map/while/PyFunc}}]] [Op:__inference_infer_788]\n",
      "Inference error: Graph execution error:\n",
      "\n",
      "Detected at node 'model/landmarks_detector_v3/map/while/PyFunc' defined at (most recent call last):\n",
      "Node: 'model/landmarks_detector_v3/map/while/PyFunc'\n",
      "ValueError: Could not find callback with key=pyfunc_13 in the registry.\n",
      "Traceback (most recent call last):\n",
      "\n",
      "  File \"D:\\Apps\\anaconda\\envs\\swara\\lib\\site-packages\\tensorflow\\python\\ops\\script_ops.py\", line 256, in __call__\n",
      "    raise ValueError(f\"Could not find callback with key={token} in the \"\n",
      "\n",
      "ValueError: Could not find callback with key=pyfunc_13 in the registry.\n",
      "\n",
      "\n",
      "\t [[{{node model/landmarks_detector_v3/map/while/PyFunc}}]] [Op:__inference_infer_788]\n",
      "Inference error: Graph execution error:\n",
      "\n",
      "Detected at node 'model/landmarks_detector_v3/map/while/PyFunc' defined at (most recent call last):\n",
      "Node: 'model/landmarks_detector_v3/map/while/PyFunc'\n",
      "ValueError: Could not find callback with key=pyfunc_13 in the registry.\n",
      "Traceback (most recent call last):\n",
      "\n",
      "  File \"D:\\Apps\\anaconda\\envs\\swara\\lib\\site-packages\\tensorflow\\python\\ops\\script_ops.py\", line 256, in __call__\n",
      "    raise ValueError(f\"Could not find callback with key={token} in the \"\n",
      "\n",
      "ValueError: Could not find callback with key=pyfunc_13 in the registry.\n",
      "\n",
      "\n",
      "\t [[{{node model/landmarks_detector_v3/map/while/PyFunc}}]] [Op:__inference_infer_788]\n",
      "Inference error: Graph execution error:\n",
      "\n",
      "Detected at node 'model/landmarks_detector_v3/map/while/PyFunc' defined at (most recent call last):\n",
      "Node: 'model/landmarks_detector_v3/map/while/PyFunc'\n",
      "ValueError: Could not find callback with key=pyfunc_13 in the registry.\n",
      "Traceback (most recent call last):\n",
      "\n",
      "  File \"D:\\Apps\\anaconda\\envs\\swara\\lib\\site-packages\\tensorflow\\python\\ops\\script_ops.py\", line 256, in __call__\n",
      "    raise ValueError(f\"Could not find callback with key={token} in the \"\n",
      "\n",
      "ValueError: Could not find callback with key=pyfunc_13 in the registry.\n",
      "\n",
      "\n",
      "\t [[{{node model/landmarks_detector_v3/map/while/PyFunc}}]] [Op:__inference_infer_788]\n",
      "Inference error: Graph execution error:\n",
      "\n",
      "Detected at node 'model/landmarks_detector_v3/map/while/PyFunc' defined at (most recent call last):\n",
      "Node: 'model/landmarks_detector_v3/map/while/PyFunc'\n",
      "ValueError: Could not find callback with key=pyfunc_13 in the registry.\n",
      "Traceback (most recent call last):\n",
      "\n",
      "  File \"D:\\Apps\\anaconda\\envs\\swara\\lib\\site-packages\\tensorflow\\python\\ops\\script_ops.py\", line 256, in __call__\n",
      "    raise ValueError(f\"Could not find callback with key={token} in the \"\n",
      "\n",
      "ValueError: Could not find callback with key=pyfunc_13 in the registry.\n",
      "\n",
      "\n",
      "\t [[{{node model/landmarks_detector_v3/map/while/PyFunc}}]] [Op:__inference_infer_788]\n",
      "Inference error: Graph execution error:\n",
      "\n",
      "Detected at node 'model/landmarks_detector_v3/map/while/PyFunc' defined at (most recent call last):\n",
      "Node: 'model/landmarks_detector_v3/map/while/PyFunc'\n",
      "ValueError: Could not find callback with key=pyfunc_13 in the registry.\n",
      "Traceback (most recent call last):\n",
      "\n",
      "  File \"D:\\Apps\\anaconda\\envs\\swara\\lib\\site-packages\\tensorflow\\python\\ops\\script_ops.py\", line 256, in __call__\n",
      "    raise ValueError(f\"Could not find callback with key={token} in the \"\n",
      "\n",
      "ValueError: Could not find callback with key=pyfunc_13 in the registry.\n",
      "\n",
      "\n",
      "\t [[{{node model/landmarks_detector_v3/map/while/PyFunc}}]] [Op:__inference_infer_788]\n",
      "Inference error: Graph execution error:\n",
      "\n",
      "Detected at node 'model/landmarks_detector_v3/map/while/PyFunc' defined at (most recent call last):\n",
      "Node: 'model/landmarks_detector_v3/map/while/PyFunc'\n",
      "ValueError: Could not find callback with key=pyfunc_13 in the registry.\n",
      "Traceback (most recent call last):\n",
      "\n",
      "  File \"D:\\Apps\\anaconda\\envs\\swara\\lib\\site-packages\\tensorflow\\python\\ops\\script_ops.py\", line 256, in __call__\n",
      "    raise ValueError(f\"Could not find callback with key={token} in the \"\n",
      "\n",
      "ValueError: Could not find callback with key=pyfunc_13 in the registry.\n",
      "\n",
      "\n",
      "\t [[{{node model/landmarks_detector_v3/map/while/PyFunc}}]] [Op:__inference_infer_788]\n",
      "Inference error: Graph execution error:\n",
      "\n",
      "Detected at node 'model/landmarks_detector_v3/map/while/PyFunc' defined at (most recent call last):\n",
      "Node: 'model/landmarks_detector_v3/map/while/PyFunc'\n",
      "ValueError: Could not find callback with key=pyfunc_13 in the registry.\n",
      "Traceback (most recent call last):\n",
      "\n",
      "  File \"D:\\Apps\\anaconda\\envs\\swara\\lib\\site-packages\\tensorflow\\python\\ops\\script_ops.py\", line 256, in __call__\n",
      "    raise ValueError(f\"Could not find callback with key={token} in the \"\n",
      "\n",
      "ValueError: Could not find callback with key=pyfunc_13 in the registry.\n",
      "\n",
      "\n",
      "\t [[{{node model/landmarks_detector_v3/map/while/PyFunc}}]] [Op:__inference_infer_788]\n",
      "Inference error: Graph execution error:\n",
      "\n",
      "Detected at node 'model/landmarks_detector_v3/map/while/PyFunc' defined at (most recent call last):\n",
      "Node: 'model/landmarks_detector_v3/map/while/PyFunc'\n",
      "ValueError: Could not find callback with key=pyfunc_13 in the registry.\n",
      "Traceback (most recent call last):\n",
      "\n",
      "  File \"D:\\Apps\\anaconda\\envs\\swara\\lib\\site-packages\\tensorflow\\python\\ops\\script_ops.py\", line 256, in __call__\n",
      "    raise ValueError(f\"Could not find callback with key={token} in the \"\n",
      "\n",
      "ValueError: Could not find callback with key=pyfunc_13 in the registry.\n",
      "\n",
      "\n",
      "\t [[{{node model/landmarks_detector_v3/map/while/PyFunc}}]] [Op:__inference_infer_788]\n"
     ]
    }
   ],
   "source": [
    "import cv2\n",
    "import numpy as np\n",
    "import tensorflow as tf\n",
    "\n",
    "# Load the SavedModel\n",
    "model_path = 'Models/Handsign_detection'  # Path to the directory containing the saved_model.pb\n",
    "model = tf.saved_model.load(model_path)\n",
    "\n",
    "# Ensure all custom objects are registered (if any)\n",
    "# from custom_objects import CustomLayer  # Example of importing custom layers\n",
    "\n",
    "# Get the inference function and wrap it in a tf.function decorator\n",
    "@tf.function\n",
    "def infer(input_tensor):\n",
    "    return model.signatures['serving_default'](input_tensor)\n",
    "\n",
    "# Function to preprocess the frame for the model\n",
    "def preprocess_frame(frame):\n",
    "    frame = cv2.cvtColor(frame, cv2.COLOR_BGR2RGB)  # Convert BGR to RGB\n",
    "    frame = cv2.resize(frame, (224, 224))  # Resize to the input size expected by the model\n",
    "    frame = np.expand_dims(frame, axis=0)  # Add batch dimension\n",
    "    frame = frame / 255.0  # Normalize pixel values\n",
    "    frame = frame.astype(np.float32)  # Ensure the data type is float32\n",
    "    return frame\n",
    "\n",
    "# Function to draw bounding box and label on the frame\n",
    "def draw_prediction(frame, boxes, classes):\n",
    "    h, w, _ = frame.shape\n",
    "    for box, cls in zip(boxes, classes):\n",
    "        ymin, xmin, ymax, xmax = box\n",
    "        (startX, startY, endX, endY) = (int(xmin * w), int(ymin * h), int(xmax * w), int(ymax * h))\n",
    "        \n",
    "        # Draw bounding box\n",
    "        cv2.rectangle(frame, (startX, startY), (endX, endY), (0, 255, 0), 2)\n",
    "        \n",
    "        # Draw label\n",
    "        label = f\"Class: {cls.numpy()}\"\n",
    "        y = startY - 10 if startY - 10 > 10 else startY + 10\n",
    "        cv2.putText(frame, label, (startX, y), cv2.FONT_HERSHEY_SIMPLEX, 0.5, (0, 255, 0), 2)\n",
    "\n",
    "# Capture video from the webcam\n",
    "cap = cv2.VideoCapture(0)\n",
    "\n",
    "while True:\n",
    "    ret, frame = cap.read()\n",
    "    if not ret:\n",
    "        break\n",
    "\n",
    "    # Preprocess the frame\n",
    "    input_data = preprocess_frame(frame)\n",
    "    input_tensor = tf.convert_to_tensor(input_data, dtype=tf.float32)\n",
    "    \n",
    "    try:\n",
    "        # Perform inference\n",
    "        outputs = infer(input_tensor)\n",
    "        \n",
    "        # Assuming the model's output contains bounding boxes and class predictions\n",
    "        detection_boxes = outputs['detection_boxes'].numpy()[0]  # Adjust key as needed\n",
    "        detection_classes = outputs['detection_classes'].numpy()[0]  # Adjust key as needed\n",
    "\n",
    "        # Draw predictions on the frame\n",
    "        draw_prediction(frame, detection_boxes, detection_classes)\n",
    "        \n",
    "        # Display the frame\n",
    "        cv2.imshow('Hand Sign Detection', frame)\n",
    "        \n",
    "    except Exception as e:\n",
    "        print(f\"Inference error: {e}\")\n",
    "    \n",
    "    # Break the loop on 'q' key press\n",
    "    if cv2.waitKey(1) & 0xFF == ord('q'):\n",
    "        break\n",
    "\n",
    "# Release the video capture object and close all OpenCV windows\n",
    "cap.release()\n",
    "cv2.destroyAllWindows()\n"
   ]
  },
  {
   "cell_type": "code",
   "execution_count": null,
   "id": "43e6de62-1191-4d2e-8ae6-03bf0fd8ff99",
   "metadata": {},
   "outputs": [],
   "source": []
  }
 ],
 "metadata": {
  "kernelspec": {
   "display_name": "Python 3 (ipykernel)",
   "language": "python",
   "name": "python3"
  },
  "language_info": {
   "codemirror_mode": {
    "name": "ipython",
    "version": 3
   },
   "file_extension": ".py",
   "mimetype": "text/x-python",
   "name": "python",
   "nbconvert_exporter": "python",
   "pygments_lexer": "ipython3",
   "version": "3.9.2"
  }
 },
 "nbformat": 4,
 "nbformat_minor": 5
}
